Workbook

Sheet RacePerformance
A1: RaceID | B1: Date | C1: RaceName | D1: FederationTotalBirds | E1: LoftTotalBirds | F1: ChickID | G1: Distance_km | H1: Speed_mpm | I1: FederationPos | J1: LoftPos | K1: RaceIndex_calc | L1: LoftRaced In
A2: KOMGA | B2: 30/05/2026 | C2: KOMGA 1 | D2: 160 | E2: 15 | F2: ZA-2025-DUVE-533 | G2: 334 | H2: 1242.984 | I2: 20 | J2: 2 | K2: =IFERROR(((D2 - I2 + 1)/D2 + (E2 - J2 + 1)/E2)/2,"") -> 0.90729167 | L2: GEORGE VAN ONSELEN
A3: BUTTERWORTH | B3: 13/06/2026 | C3: BUTTERWORTH 1 | D3: 133 | E3: 15 | F3: ZA-2025-DUVE-527 | G3: 369 | H3: 971.337 | I3: 47 | J3: 3 | K3: =IFERROR(((D3 - I3 + 1)/D3 + (E3 - J3 + 1)/E3)/2,"") -> 0.760401 | L3: GEORGE VAN ONSELEN
A4: BUTTERWORTH | B4: 13/06/2026 | C4: BUTTERWORTH 1 | D4: 133 | E4: 15 | F4: ZA-2025-DUVE-548 | G4: 369 | H4: 970.996 | I4: 48 | J4: 4 | K4: =IFERROR(((D4 - I4 + 1)/D4 + (E4 - J4 + 1)/E4)/2,"") -> 0.72330827 | L4: GEORGE VAN ONSELEN
A5: KOMGA | B5: 07/06/2026 | C5: KOMGA 2 | D5: 161 | E5: 15 | F5: ZA-2025-DUVE-527 | G5: 334 | H5: 1059.09 | I5: 58 | J5: 4 | K5: =IFERROR(((D5 - I5 + 1)/D5 + (E5 - J5 + 1)/E5)/2,"") -> 0.72298137 | L5: GEORGE VAN ONSELEN
A6: BUTTERWORTH | B6: 13/06/2026 | C6: BUTTERWORTH 1 | D6: 133 | E6: 15 | F6: ZA-2025-DUVE-512 | G6: 369 | H6: 960.508 | I6: 52 | J6: 5 | K6: =IFERROR(((D6 - I6 + 1)/D6 + (E6 - J6 + 1)/E6)/2,"") -> 0.67493734 | L6: GEORGE VAN ONSELEN
A7: BUTTERWORTH | B7: 13/06/2026 | C7: BUTTERWORTH 1 | D7: 133 | E7: 15 | F7: ZA-2025-DUVE-578 | G7: 369 | H7: 960.216 | I7: 53 | J7: 6 | K7: =IFERROR(((D7 - I7 + 1)/D7 + (E7 - J7 + 1)/E7)/2,"") -> 0.63784461 | L7: GEORGE VAN ONSELEN
A8: MIDDELBURG | B8: 07/06/2026 | C8: MIDDELBURG 2 | D8: 161 | E8: 15 | F8: ZA-2025-DUVE-536 | G8: 280 | H8: 1067.239 | I8: 66 | J8: 6 | K8: =IFERROR(((D8 - I8 + 1)/D8 + (E8 - J8 + 1)/E8)/2,"") -> 0.63146998 | L8: GEORGE VAN ONSELEN
A9: KOMGA | B9: 30/05/2026 | C9: KOMGA 1 | D9: 160 | E9: 15 | F9: ZA-2025-DUVE-557 | G9: 334 | H9: 1125.713 | I9: 79 | J9: 8 | K9: =IFERROR(((D9 - I9 + 1)/D9 + (E9 - J9 + 1)/E9)/2,"") -> 0.52291667 | L9: GEORGE VAN ONSELEN
A10: KOMGA | B10: 07/06/2026 | C10: KOMGA 2 | D10: 161 | E10: 15 | F10: ZA-2025-DUVE-512 | G10: 334 | H10: 755.752 | I10: 92 | J10: 8 | K10: =IFERROR(((D10 - I10 + 1)/D10 + (E10 - J10 + 1)/E10)/2,"") -> 0.48405797 | L10: GEORGE VAN ONSELEN
A11: KOMGA | B11: 07/06/2026 | C11: KOMGA 2 | D11: 161 | E11: 15 | F11: ZA-2025-DUVE-530 | G11: 334 | H11: 236.92 | I11: 103 | J11: 9 | K11: =IFERROR(((D11 - I11 + 1)/D11 + (E11 - J11 + 1)/E11)/2,"") -> 0.41656315 | L11: GEORGE VAN ONSELEN
A12: BUTTERWORTH | B12: 13/06/2026 | C12: BUTTERWORTH 1 | D12: 133 | E12: 15 | F12: ZA-2025-DUVE-533 | G12: 369 | H12: 883.083 | I12: 79 | J12: 10 | K12: =IFERROR(((D12 - I12 + 1)/D12 + (E12 - J12 + 1)/E12)/2,"") -> 0.40676692 | L12: GEORGE VAN ONSELEN
A13: BUTTERWORTH | B13: 13/06/2026 | C13: BUTTERWORTH 1 | D13: 133 | E13: 15 | F13: ZA-2025-DUVE-558 | G13: 369 | H13: 842.331 | I13: 89 | J13: 11 | K13: =IFERROR(((D13 - I13 + 1)/D13 + (E13 - J13 + 1)/E13)/2,"") -> 0.3358396 | L13: GEORGE VAN ONSELEN
... A17: BUTTERWORTH | B17: 13/06/2026 | C17: BUTTERWORTH 1 | D17: 133 | E17: 15 | F17: ZA-2025-DUVE-536 | G17: 369 | H17: 243.714 | I17: 107 | J17: 14 | K17: =IFERROR(((D17 - I17 + 1)/D17 + (E17 - J17 + 1)/E17)/2,"") -> 0.16817043 | L17: GEORGE VAN ONSELEN

Sheet Chicks
A1: ChickID | B1: Ring | C1: RoundNumber | D1: HatchDate | E1: RaisedbyFeeders | F1: SireID | G1: DamID | H1: Pre-Season Rating | I1: InLoftsSeasonStart | J1: TotalRaces | K1: AvgFederationPos | L1: AvgLoftPos | M1: AverageRaceIndex | N1: Top20FedFinishes | O1: FedWins | P1: Loft top 3
A2: ZA-2025-DUVE-502 | B2: 502 | C2: 1 | D2: 45904 | F2: ZA-2015-OP-7903 | G2: ZA-2019-OP-9331 | H2: 80 | I2: Yes | J2: =IF(A2="","",COUNTIF(RacePerformance!$F:$F,A2)) -> 0 | K2: =IF(A2="","",IFERROR(AVERAGEIF(RacePerformance!$F:$F,A2,RacePerformance!$I:$I),"")) | L2: =IF(A2="","",IFERROR(AVERAGEIF(RacePerformance!$F:$F,A2,RacePerformance!$J:$J),"")) | M2: =IF(A2="","",IFERROR(AVERAGEIF(RacePerformance!$F:$F,A2,RacePerformance!$K:$K),"")) | N2: =IF(A2="","",COUNTIFS(RacePerformance!$F:$F,A2,RacePerformance!$I:$I,"<=20")) -> 0 | O2: =IF(A2="","",COUNTIFS(RacePerformance!$F:$F,A2,RacePerformance!$I:$I,1)) -> 0 | P2: =IF(A2="","",COUNTIFS(RacePerformance!$F:$F,A2,RacePerformance!$J:$J,"<=3")) -> 0 | R2: 502
A3: ZA-2025-DUVE-512 | B3: 512 | C3: 1 | D3: 45904 | F3: ZA-2015-OP-7903 | G3: ZA-2019-OP-9331 | H3: 75 | I3: Yes | J3: =IF(A3="","",COUNTIF(RacePerformance!$F:$F,A3)) -> 2 | K3: =IF(A3="","",IFERROR(AVERAGEIF(RacePerformance!$F:$F,A3,RacePerformance!$I:$I),"")) -> 72 | L3: =IF(A3="","",IFERROR(AVERAGEIF(RacePerformance!$F:$F,A3,RacePerformance!$J:$J),"")) -> 6.5 | M3: =IF(A3="","",IFERROR(AVERAGEIF(RacePerformance!$F:$F,A3,RacePerformance!$K:$K),"")) -> 0.57949766 | N3: =IF(A3="","",COUNTIFS(RacePerformance!$F:$F,A3,RacePerformance!$I:$I,"<=20")) -> 0 | O3: =IF(A3="","",COUNTIFS(RacePerformance!$F:$F,A3,RacePerformance!$I:$I,1)) -> 0 | P3: =IF(A3="","",COUNTIFS(RacePerformance!$F:$F,A3,RacePerformance!$J:$J,"<=3")) -> 0 | R3: 506
A4: ZA-2025-DUVE-507 | B4: 507 | C4: 1 | D4: 45859 | F4: ZA-2019-OPJB-251 | G4: ZA-2020-OP-17032 | I4: No | J4: =IF(A4="","",COUNTIF(RacePerformance!$F:$F,A4)) -> 0 | K4: =IF(A4="","",IFERROR(AVERAGEIF(RacePerformance!$F:$F,A4,RacePerformance!$I:$I),"")) | L4: =IF(A4="","",IFERROR(AVERAGEIF(RacePerformance!$F:$F,A4,RacePerformance!$J:$J),"")) | M4: =IF(A4="","",IFERROR(AVERAGEIF(RacePerformance!$F:$F,A4,RacePerformance!$K:$K),"")) | N4: =IF(A4="","",COUNTIFS(RacePerformance!$F:$F,A4,RacePerformance!$I:$I,"<=20")) -> 0 | O4: =IF(A4="","",COUNTIFS(RacePerformance!$F:$F,A4,RacePerformance!$I:$I,1)) -> 0 | P4: =IF(A4="","",COUNTIFS(RacePerformance!$F:$F,A4,RacePerformance!$J:$J,"<=3")) -> 0 | R4: 512
A5: ZA-2025-DUVE-527 | B5: 527 | C5: 2 | D5: 45904 | F5: ZA-2019-OPJB-251 | G5: ZA-2020-OP-17032 | H5: 85 | I5: Yes | J5: =IF(A5="","",COUNTIF(RacePerformance!$F:$F,A5)) -> 2 | K5: =IF(A5="","",IFERROR(AVERAGEIF(RacePerformance!$F:$F,A5,RacePerformance!$I:$I),"")) -> 52.5 | L5: =IF(A5="","",IFERROR(AVERAGEIF(RacePerformance!$F:$F,A5,RacePerformance!$J:$J),"")) -> 3.5 | M5: =IF(A5="","",IFERROR(AVERAGEIF(RacePerformance!$F:$F,A5,RacePerformance!$K:$K),"")) -> 0.74169118 | N5: =IF(A5="","",COUNTIFS(RacePerformance!$F:$F,A5,RacePerformance!$I:$I,"<=20")) -> 0 | O5: =IF(A5="","",COUNTIFS(RacePerformance!$F:$F,A5,RacePerformance!$I:$I,1)) -> 0 | P5: =IF(A5="","",COUNTIFS(RacePerformance!$F:$F,A5,RacePerformance!$J:$J,"<=3")) -> 1 | R5: 516
A6: ZA-2025-DUVE-537 | B6: 537 | C6: 2 | D6: 45904 | F6: ZA-2019-OPJB-251 | G6: ZA-2020-OP-17032 | H6: 80 | I6: Yes | J6: =IF(A6="","",COUNTIF(RacePerformance!$F:$F,A6)) -> 0 | K6: =IF(A6="","",IFERROR(AVERAGEIF(RacePerformance!$F:$F,A6,RacePerformance!$I:$I),"")) | L6: =IF(A6="","",IFERROR(AVERAGEIF(RacePerformance!$F:$F,A6,RacePerformance!$J:$J),"")) | M6: =IF(A6="","",IFERROR(AVERAGEIF(RacePerformance!$F:$F,A6,RacePerformance!$K:$K),"")) | N6: =IF(A6="","",COUNTIFS(RacePerformance!$F:$F,A6,RacePerformance!$I:$I,"<=20")) -> 0 | O6: =IF(A6="","",COUNTIFS(RacePerformance!$F:$F,A6,RacePerformance!$I:$I,1)) -> 0 | P6: =IF(A6="","",COUNTIFS(RacePerformance!$F:$F,A6,RacePerformance!$J:$J,"<=3")) -> 0 | R6: 520
A7: ZA-2025-DUVE-517 | B7: 517 | C7: 1 | D7: 45859 | F7: ZA-2019-OPJB-251 | G7: ZA-2020-OP-17032 | H7: 70 | I7: No | J7: =IF(A7="","",COUNTIF(RacePerformance!$F:$F,A7)) -> 0 | K7: =IF(A7="","",IFERROR(AVERAGEIF(RacePerformance!$F:$F,A7,RacePerformance!$I:$I),"")) | L7: =IF(A7="","",IFERROR(AVERAGEIF(RacePerformance!$F:$F,A7,RacePerformance!$J:$J),"")) | M7: =IF(A7="","",IFERROR(AVERAGEIF(RacePerformance!$F:$F,A7,RacePerformance!$K:$K),"")) | N7: =IF(A7="","",COUNTIFS(RacePerformance!$F:$F,A7,RacePerformance!$I:$I,"<=20")) -> 0 | O7: =IF(A7="","",COUNTIFS(RacePerformance!$F:$F,A7,RacePerformance!$I:$I,1)) -> 0 | P7: =IF(A7="","",COUNTIFS(RacePerformance!$F:$F,A7,RacePerformance!$J:$J,"<=3")) -> 0 | R7: 525
A8: ZA-2025-DUVE-557 | B8: 557 | C8: 2 | D8: 45943 | F8: ZA-2019-OPJB-251 | G8: ZA-2020-OP-17032 | H8: 85 | I8: Yes | J8: =IF(A8="","",COUNTIF(RacePerformance!$F:$F,A8)) -> 1 | K8: =IF(A8="","",IFERROR(AVERAGEIF(RacePerformance!$F:$F,A8,RacePerformance!$I:$I),"")) -> 79 | L8: =IF(A8="","",IFERROR(AVERAGEIF(RacePerformance!$F:$F,A8,RacePerformance!$J:$J),"")) -> 8 | M8: =IF(A8="","",IFERROR(AVERAGEIF(RacePerformance!$F:$F,A8,RacePerformance!$K:$K),"")) -> 0.52291667 | N8: =IF(A8="","",COUNTIFS(RacePerformance!$F:$F,A8,RacePerformance!$I:$I,"<=20")) -> 0 | O8: =IF(A8="","",COUNTIFS(RacePerformance!$F:$F,A8,RacePerformance!$I:$I,1)) -> 0 | P8: =IF(A8="","",COUNTIFS(RacePerformance!$F:$F,A8,RacePerformance!$J:$J,"<=3")) -> 0 | R8: 527
A9: ZA-2025-DUVE-547 | B9: 547 | C9: 2 | D9: 45943 | F9: ZA-2019-OPJB-251 | G9: ZA-2020-OP-17032 | H9: 85 | I9: No | J9: =IF(A9="","",COUNTIF(RacePerformance!$F:$F,A9)) -> 0 | K9: =IF(A9="","",IFERROR(AVERAGEIF(RacePerformance!$F:$F,A9,RacePerformance!$I:$I),"")) | L9: =IF(A9="","",IFERROR(AVERAGEIF(RacePerformance!$F:$F,A9,RacePerformance!$J:$J),"")) | M9: =IF(A9="","",IFERROR(AVERAGEIF(RacePerformance!$F:$F,A9,RacePerformance!$K:$K),"")) | N9: =IF(A9="","",COUNTIFS(RacePerformance!$F:$F,A9,RacePerformance!$I:$I,"<=20")) -> 0 | O9: =IF(A9="","",COUNTIFS(RacePerformance!$F:$F,A9,RacePerformance!$I:$I,1)) -> 0 | P9: =IF(A9="","",COUNTIFS(RacePerformance!$F:$F,A9,RacePerformance!$J:$J,"<=3")) -> 0 | R9: 528
A10: ZA-2025-DUVE-503 | B10: 503 | C10: 1 | D10: 45858 | F10: ZA-2020-OP-19773 | G10: ZA-2022-DUVE-255 | H10: 85 | I10: No | J10: =IF(A10="","",COUNTIF(RacePerformance!$F:$F,A10)) -> 0 | K10: =IF(A10="","",IFERROR(AVERAGEIF(RacePerformance!$F:$F,A10,RacePerformance!$I:$I),"")) | L10: =IF(A10="","",IFERROR(AVERAGEIF(RacePerformance!$F:$F,A10,RacePerformance!$J:$J),"")) | M10: =IF(A10="","",IFERROR(AVERAGEIF(RacePerformance!$F:$F,A10,RacePerformance!$K:$K),"")) | N10: =IF(A10="","",COUNTIFS(RacePerformance!$F:$F,A10,RacePerformance!$I:$I,"<=20")) -> 0 | O10: =IF(A10="","",COUNTIFS(RacePerformance!$F:$F,A10,RacePerformance!$I:$I,1)) -> 0 | P10: =IF(A10="","",COUNTIFS(RacePerformance!$F:$F,A10,RacePerformance!$J:$J,"<=3")) -> 0 | R10: 530
A11: ZA-2025-DUVE-513 | B11: 513 | C11: 1 | D11: 45858 | F11: ZA-2020-OP-19773 | G11: ZA-2022-DUVE-255 | H11: 85 | I11: No | J11: =IF(A11="","",COUNTIF(RacePerformance!$F:$F,A11)) -> 0 | K11: =IF(A11="","",IFERROR(AVERAGEIF(RacePerformance!$F:$F,A11,RacePerformance!$I:$I),"")) | L11: =IF(A11="","",IFERROR(AVERAGEIF(RacePerformance!$F:$F,A11,RacePerformance!$J:$J),"")) | M11: =IF(A11="","",IFERROR(AVERAGEIF(RacePerformance!$F:$F,A11,RacePerformance!$K:$K),"")) | N11: =IF(A11="","",COUNTIFS(RacePerformance!$F:$F,A11,RacePerformance!$I:$I,"<=20")) -> 0 | O11: =IF(A11="","",COUNTIFS(RacePerformance!$F:$F,A11,RacePerformance!$I:$I,1)) -> 0 | P11: =IF(A11="","",COUNTIFS(RacePerformance!$F:$F,A11,RacePerformance!$J:$J,"<=3")) -> 0 | R11: 533
A12: ZA-2025-DUVE-523 | B12: 523 | C12: 2 | D12: 45903 | F12: ZA-2020-OP-19773 | G12: ZA-2022-DUVE-255 | H12: 75 | I12: No | J12: =IF(A12="","",COUNTIF(RacePerformance!$F:$F,A12)) -> 0 | K12: =IF(A12="","",IFERROR(AVERAGEIF(RacePerformance!$F:$F,A12,RacePerformance!$I:$I),"")) | L12: =IF(A12="","",IFERROR(AVERAGEIF(RacePerformance!$F:$F,A12,RacePerformance!$J:$J),"")) | M12: =IF(A12="","",IFERROR(AVERAGEIF(RacePerformance!$F:$F,A12,RacePerformance!$K:$K),"")) | N12: =IF(A12="","",COUNTIFS(RacePerformance!$F:$F,A12,RacePerformance!$I:$I,"<=20")) -> 0 | O12: =IF(A12="","",COUNTIFS(RacePerformance!$F:$F,A12,RacePerformance!$I:$I,1)) -> 0 | P12: =IF(A12="","",COUNTIFS(RacePerformance!$F:$F,A12,RacePerformance!$J:$J,"<=3")) -> 0 | R12: 536
A13: ZA-2025-DUVE-533 | B13: 533 | C13: 2 | D13: 45903 | F13: ZA-2020-OP-19773 | G13: ZA-2022-DUVE-255 | H13: 90 | I13: Yes | J13: =IF(A13="","",COUNTIF(RacePerformance!$F:$F,A13)) -> 2 | K13: =IF(A13="","",IFERROR(AVERAGEIF(RacePerformance!$F:$F,A13,RacePerformance!$I:$I),"")) -> 49.5 | L13: =IF(A13="","",IFERROR(AVERAGEIF(RacePerformance!$F:$F,A13,RacePerformance!$J:$J),"")) -> 6 | M13: =IF(A13="","",IFERROR(AVERAGEIF(RacePerformance!$F:$F,A13,RacePerformance!$K:$K),"")) -> 0.65702929 | N13: =IF(A13="","",COUNTIFS(RacePerformance!$F:$F,A13,RacePerformance!$I:$I,"<=20")) -> 1 | O13: =IF(A13="","",COUNTIFS(RacePerformance!$F:$F,A13,RacePerformance!$I:$I,1)) -> 0 | P13: =IF(A13="","",COUNTIFS(RacePerformance!$F:$F,A13,RacePerformance!$J:$J,"<=3")) -> 1 | R13: 537
A14: ZA-2025-DUVE-543 | B14: 543 | C14: 3 | D14: 45937 | F14: ZA-2020-OP-19773 | G14: ZA-2022-DUVE-255 | H14: 75 | I14: No | J14: =IF(A14="","",COUNTIF(RacePerformance!$F:$F,A14)) -> 0 | K14: =IF(A14="","",IFERROR(AVERAGEIF(RacePerformance!$F:$F,A14,RacePerformance!$I:$I),"")) | L14: =IF(A14="","",IFERROR(AVERAGEIF(RacePerformance!$F:$F,A14,RacePerformance!$J:$J),"")) | M14: =IF(A14="","",IFERROR(AVERAGEIF(RacePerformance!$F:$F,A14,RacePerformance!$K:$K),"")) | N14: =IF(A14="","",COUNTIFS(RacePerformance!$F:$F,A14,RacePerformance!$I:$I,"<=20")) -> 0 | O14: =IF(A14="","",COUNTIFS(RacePerformance!$F:$F,A14,RacePerformance!$I:$I,1)) -> 0 | P14: =IF(A14="","",COUNTIFS(RacePerformance!$F:$F,A14,RacePerformance!$J:$J,"<=3")) -> 0 | R14: 538
A15: ZA-2025-DUVE-553 | B15: 553 | C15: 3 | D15: 45937 | F15: ZA-2020-OP-19773 | G15: ZA-2022-DUVE-255 | H15: 85 | I15: No | J15: =IF(A15="","",COUNTIF(RacePerformance!$F:$F,A15)) -> 0 | K15: =IF(A15="","",IFERROR(AVERAGEIF(RacePerformance!$F:$F,A15,RacePerformance!$I:$I),"")) | L15: =IF(A15="","",IFERROR(AVERAGEIF(RacePerformance!$F:$F,A15,RacePerformance!$J:$J),"")) | M15: =IF(A15="","",IFERROR(AVERAGEIF(RacePerformance!$F:$F,A15,RacePerformance!$K:$K),"")) | N15: =IF(A15="","",COUNTIFS(RacePerformance!$F:$F,A15,RacePerformance!$I:$I,"<=20")) -> 0 | O15: =IF(A15="","",COUNTIFS(RacePerformance!$F:$F,A15,RacePerformance!$I:$I,1)) -> 0 | P15: =IF(A15="","",COUNTIFS(RacePerformance!$F:$F,A15,RacePerformance!$J:$J,"<=3")) -> 0 | R15: 540
A16: ZA-2025-DUVE-563 | B16: 563 | C16: 4 | D16: 45967 | E16: Yes | F16: ZA-2020-OP-19773 | G16: ZA-2022-DUVE-255 | H16: 70 | I16: No | J16: =IF(A16="","",COUNTIF(RacePerformance!$F:$F,A16)) -> 0 | K16: =IF(A16="","",IFERROR(AVERAGEIF(RacePerformance!$F:$F,A16,RacePerformance!$I:$I),"")) | L16: =IF(A16="","",IFERROR(AVERAGEIF(RacePerformance!$F:$F,A16,RacePerformance!$J:$J),"")) | M16: =IF(A16="","",IFERROR(AVERAGEIF(RacePerformance!$F:$F,A16,RacePerformance!$K:$K),"")) | N16: =IF(A16="","",COUNTIFS(RacePerformance!$F:$F,A16,RacePerformance!$I:$I,"<=20")) -> 0 | O16: =IF(A16="","",COUNTIFS(RacePerformance!$F:$F,A16,RacePerformance!$I:$I,1)) -> 0 | P16: =IF(A16="","",COUNTIFS(RacePerformance!$F:$F,A16,RacePerformance!$J:$J,"<=3")) -> 0 | R16: 546
A17: ZA-2025-DUVE-505 | B17: 505 | C17: 1 | D17: 45843 | E17: Yes | F17: ZA-2022-DUVE-240 | G17: ZA-2019-OP-9331 | H17: 85 | I17: No | J17: =IF(A17="","",COUNTIF(RacePerformance!$F:$F,A17)) -> 0 | K17: =IF(A17="","",IFERROR(AVERAGEIF(RacePerformance!$F:$F,A17,RacePerformance!$I:$I),"")) | L17: =IF(A17="","",IFERROR(AVERAGEIF(RacePerformance!$F:$F,A17,RacePerformance!$J:$J),"")) | M17: =IF(A17="","",IFERROR(AVERAGEIF(RacePerformance!$F:$F,A17,RacePerformance!$K:$K),"")) | N17: =IF(A17="","",COUNTIFS(RacePerformance!$F:$F,A17,RacePerformance!$I:$I,"<=20")) -> 0 | O17: =IF(A17="","",COUNTIFS(RacePerformance!$F:$F,A17,RacePerformance!$I:$I,1)) -> 0 | P17: =IF(A17="","",COUNTIFS(RacePerformance!$F:$F,A17,RacePerformance!$J:$J,"<=3")) -> 0 | R17: 548
A18: ZA-2025-DUVE-515 | B18: 515 | C18: 2 | D18: 45918 | E18: Yes | F18: ZA-2022-DUVE-240 | G18: ZA-2022-DUVE-243 | I18: No | J18: =IF(A18="","",COUNTIF(RacePerformance!$F:$F,A18)) -> 0 | K18: =IF(A18="","",IFERROR(AVERAGEIF(RacePerformance!$F:$F,A18,RacePerformance!$I:$I),"")) | L18: =IF(A18="","",IFERROR(AVERAGEIF(RacePerformance!$F:$F,A18,RacePerformance!$J:$J),"")) | M18: =IF(A18="","",IFERROR(AVERAGEIF(RacePerformance!$F:$F,A18,RacePerformance!$K:$K),"")) | N18: =IF(A18="","",COUNTIFS(RacePerformance!$F:$F,A18,RacePerformance!$I:$I,"<=20")) -> 0 | O18: =IF(A18="","",COUNTIFS(RacePerformance!$F:$F,A18,RacePerformance!$I:$I,1)) -> 0 | P18: =IF(A18="","",COUNTIFS(RacePerformance!$F:$F,A18,RacePerformance!$J:$J,"<=3")) -> 0 | R18: 556
A19: ZA-2025-DUVE-525 | B19: 525 | C19: 2 | D19: 45918 | E19: Yes | F19: ZA-2022-DUVE-240 | G19: ZA-2022-DUVE-243 | H19: 80 | I19: Yes | J19: =IF(A19="","",COUNTIF(RacePerformance!$F:$F,A19)) -> 0 | K19: =IF(A19="","",IFERROR(AVERAGEIF(RacePerformance!$F:$F,A19,RacePerformance!$I:$I),"")) | L19: =IF(A19="","",IFERROR(AVERAGEIF(RacePerformance!$F:$F,A19,RacePerformance!$J:$J),"")) | M19: =IF(A19="","",IFERROR(AVERAGEIF(RacePerformance!$F:$F,A19,RacePerformance!$K:$K),"")) | N19: =IF(A19="","",COUNTIFS(RacePerformance!$F:$F,A19,RacePerformance!$I:$I,"<=20")) -> 0 | O19: =IF(A19="","",COUNTIFS(RacePerformance!$F:$F,A19,RacePerformance!$I:$I,1)) -> 0 | P19: =IF(A19="","",COUNTIFS(RacePerformance!$F:$F,A19,RacePerformance!$J:$J,"<=3")) -> 0
A20: ZA-2025-DUVE-526 | B20: 526 | C20: 2 | D20: 45925 | F20: ZA-2022-DUVE-241 | G20: ZA-2022-DUVE-233 | H20: 90 | I20: No | J20: =IF(A20="","",COUNTIF(RacePerformance!$F:$F,A20)) -> 0 | K20: =IF(A20="","",IFERROR(AVERAGEIF(RacePerformance!$F:$F,A20,RacePerformance!$I:$I),"")) | L20: =IF(A20="","",IFERROR(AVERAGEIF(RacePerformance!$F:$F,A20,RacePerformance!$J:$J),"")) | M20: =IF(A20="","",IFERROR(AVERAGEIF(RacePerformance!$F:$F,A20,RacePerformance!$K:$K),"")) | N20: =IF(A20="","",COUNTIFS(RacePerformance!$F:$F,A20,RacePerformance!$I:$I,"<=20")) -> 0 | O20: =IF(A20="","",COUNTIFS(RacePerformance!$F:$F,A20,RacePerformance!$I:$I,1)) -> 0 | P20: =IF(A20="","",COUNTIFS(RacePerformance!$F:$F,A20,RacePerformance!$J:$J,"<=3")) -> 0
A21: ZA-2025-DUVE-506 | B21: 506 | C21: 1 | D21: 45868 | F21: ZA-2022-DUVE-241 | G21: ZA-2022-DUVE-233 | H21: 85 | I21: Yes | J21: =IF(A21="","",COUNTIF(RacePerformance!$F:$F,A21)) -> 0 | K21: =IF(A21="","",IFERROR(AVERAGEIF(RacePerformance!$F:$F,A21,RacePerformance!$I:$I),"")) | L21: =IF(A21="","",IFERROR(AVERAGEIF(RacePerformance!$F:$F,A21,RacePerformance!$J:$J),"")) | M21: =IF(A21="","",IFERROR(AVERAGEIF(RacePerformance!$F:$F,A21,RacePerformance!$K:$K),"")) | N21: =IF(A21="","",COUNTIFS(RacePerformance!$F:$F,A21,RacePerformance!$I:$I,"<=20")) -> 0 | O21: =IF(A21="","",COUNTIFS(RacePerformance!$F:$F,A21,RacePerformance!$I:$I,1)) -> 0 | P21: =IF(A21="","",COUNTIFS(RacePerformance!$F:$F,A21,RacePerformance!$J:$J,"<=3")) -> 0
A22: ZA-2025-DUVE-516 | B22: 516 | C22: 1 | D22: 45868 | F22: ZA-2022-DUVE-241 | G22: ZA-2022-DUVE-233 | H22: 85 | I22: Yes | J22: =IF(A22="","",COUNTIF(RacePerformance!$F:$F,A22)) -> 0 | K22: =IF(A22="","",IFERROR(AVERAGEIF(RacePerformance!$F:$F,A22,RacePerformance!$I:$I),"")) | L22: =IF(A22="","",IFERROR(AVERAGEIF(RacePerformance!$F:$F,A22,RacePerformance!$J:$J),"")) | M22: =IF(A22="","",IFERROR(AVERAGEIF(RacePerformance!$F:$F,A22,RacePerformance!$K:$K),"")) | N22: =IF(A22="","",COUNTIFS(RacePerformance!$F:$F,A22,RacePerformance!$I:$I,"<=20")) -> 0 | O22: =IF(A22="","",COUNTIFS(RacePerformance!$F:$F,A22,RacePerformance!$I:$I,1)) -> 0 | P22: =IF(A22="","",COUNTIFS(RacePerformance!$F:$F,A22,RacePerformance!$J:$J,"<=3")) -> 0
A23: ZA-2025-DUVE-536 | B23: 536 | C23: 2 | D23: 45925 | F23: ZA-2022-DUVE-241 | G23: ZA-2022-DUVE-233 | H23: 85 | I23: Yes | J23: =IF(A23="","",COUNTIF(RacePerformance!$F:$F,A23)) -> 2 | K23: =IF(A23="","",IFERROR(AVERAGEIF(RacePerformance!$F:$F,A23,RacePerformance!$I:$I),"")) -> 86.5 | L23: =IF(A23="","",IFERROR(AVERAGEIF(RacePerformance!$F:$F,A23,RacePerformance!$J:$J),"")) -> 10 | M23: =IF(A23="","",IFERROR(AVERAGEIF(RacePerformance!$F:$F,A23,RacePerformance!$K:$K),"")) -> 0.3998202 | N23: =IF(A23="","",COUNTIFS(RacePerformance!$F:$F,A23,RacePerformance!$I:$I,"<=20")) -> 0 | O23: =IF(A23="","",COUNTIFS(RacePerformance!$F:$F,A23,RacePerformance!$I:$I,1)) -> 0 | P23: =IF(A23="","",COUNTIFS(RacePerformance!$F:$F,A23,RacePerformance!$J:$J,"<=3")) -> 0
A24: ZA-2025-DUVE-546 | B24: 546 | C24: 3 | D24: 45966 | F24: ZA-2022-DUVE-241 | G24: ZA-2022-DUVE-233 | H24: 75 | I24: Yes | J24: =IF(A24="","",COUNTIF(RacePerformance!$F:$F,A24)) -> 0 | K24: =IF(A24="","",IFERROR(AVERAGEIF(RacePerformance!$F:$F,A24,RacePerformance!$I:$I),"")) | L24: =IF(A24="","",IFERROR(AVERAGEIF(RacePerformance!$F:$F,A24,RacePerformance!$J:$J),"")) | M24: =IF(A24="","",IFERROR(AVERAGEIF(RacePerformance!$F:$F,A24,RacePerformance!$K:$K),"")) | N24: =IF(A24="","",COUNTIFS(RacePerformance!$F:$F,A24,RacePerformance!$I:$I,"<=20")) -> 0 | O24: =IF(A24="","",COUNTIFS(RacePerformance!$F:$F,A24,RacePerformance!$I:$I,1)) -> 0 | P24: =IF(A24="","",COUNTIFS(RacePerformance!$F:$F,A24,RacePerformance!$J:$J,"<=3")) -> 0
A25: ZA-2025-DUVE-556 | B25: 556 | C25: 3 | D25: 45966 | F25: ZA-2022-DUVE-241 | G25: ZA-2022-DUVE-233 | H25: 85 | I25: Yes | J25: =IF(A25="","",COUNTIF(RacePerformance!$F:$F,A25)) -> 0 | K25: =IF(A25="","",IFERROR(AVERAGEIF(RacePerformance!$F:$F,A25,RacePerformance!$I:$I),"")) | L25: =IF(A25="","",IFERROR(AVERAGEIF(RacePerformance!$F:$F,A25,RacePerformance!$J:$J),"")) | M25: =IF(A25="","",IFERROR(AVERAGEIF(RacePerformance!$F:$F,A25,RacePerformance!$K:$K),"")) | N25: =IF(A25="","",COUNTIFS(RacePerformance!$F:$F,A25,RacePerformance!$I:$I,"<=20")) -> 0 | O25: =IF(A25="","",COUNTIFS(RacePerformance!$F:$F,A25,RacePerformance!$I:$I,1)) -> 0 | P25: =IF(A25="","",COUNTIFS(RacePerformance!$F:$F,A25,RacePerformance!$J:$J,"<=3")) -> 0
A26: ZA-2025-DUVE-508 | B26: 508 | C26: 1 | D26: 45843 | F26: ZA-2022-DUVE-302 | G26: ZA-2020-OPDP-2190 | H26: 85 | I26: No | J26: =IF(A26="","",COUNTIF(RacePerformance!$F:$F,A26)) -> 0 | K26: =IF(A26="","",IFERROR(AVERAGEIF(RacePerformance!$F:$F,A26,RacePerformance!$I:$I),"")) | L26: =IF(A26="","",IFERROR(AVERAGEIF(RacePerformance!$F:$F,A26,RacePerformance!$J:$J),"")) | M26: =IF(A26="","",IFERROR(AVERAGEIF(RacePerformance!$F:$F,A26,RacePerformance!$K:$K),"")) | N26: =IF(A26="","",COUNTIFS(RacePerformance!$F:$F,A26,RacePerformance!$I:$I,"<=20")) -> 0 | O26: =IF(A26="","",COUNTIFS(RacePerformance!$F:$F,A26,RacePerformance!$I:$I,1)) -> 0 | P26: =IF(A26="","",COUNTIFS(RacePerformance!$F:$F,A26,RacePerformance!$J:$J,"<=3")) -> 0
A27: ZA-2025-DUVE-518 | B27: 518 | C27: 1 | D27: 45843 | F27: ZA-2022-DUVE-302 | G27: ZA-2020-OPDP-2190 | H27: 90 | I27: No | J27: =IF(A27="","",COUNTIF(RacePerformance!$F:$F,A27)) -> 0 | K27: =IF(A27="","",IFERROR(AVERAGEIF(RacePerformance!$F:$F,A27,RacePerformance!$I:$I),"")) | L27: =IF(A27="","",IFERROR(AVERAGEIF(RacePerformance!$F:$F,A27,RacePerformance!$J:$J),"")) | M27: =IF(A27="","",IFERROR(AVERAGEIF(RacePerformance!$F:$F,A27,RacePerformance!$K:$K),"")) | N27: =IF(A27="","",COUNTIFS(RacePerformance!$F:$F,A27,RacePerformance!$I:$I,"<=20")) -> 0 | O27: =IF(A27="","",COUNTIFS(RacePerformance!$F:$F,A27,RacePerformance!$I:$I,1)) -> 0 | P27: =IF(A27="","",COUNTIFS(RacePerformance!$F:$F,A27,RacePerformance!$J:$J,"<=3")) -> 0
A28: ZA-2025-DUVE-528 | B28: 528 | C28: 2 | D28: 45925 | E28: Yes | F28: ZA-2022-DUVE-302 | G28: ZA-2020-OPDP-2190 | H28: 85 | I28: Yes | J28: =IF(A28="","",COUNTIF(RacePerformance!$F:$F,A28)) -> 0 | K28: =IF(A28="","",IFERROR(AVERAGEIF(RacePerformance!$F:$F,A28,RacePerformance!$I:$I),"")) | L28: =IF(A28="","",IFERROR(AVERAGEIF(RacePerformance!$F:$F,A28,RacePerformance!$J:$J),"")) | M28: =IF(A28="","",IFERROR(AVERAGEIF(RacePerformance!$F:$F,A28,RacePerformance!$K:$K),"")) | N28: =IF(A28="","",COUNTIFS(RacePerformance!$F:$F,A28,RacePerformance!$I:$I,"<=20")) -> 0 | O28: =IF(A28="","",COUNTIFS(RacePerformance!$F:$F,A28,RacePerformance!$I:$I,1)) -> 0 | P28: =IF(A28="","",COUNTIFS(RacePerformance!$F:$F,A28,RacePerformance!$J:$J,"<=3")) -> 0
A29: ZA-2025-DUVE-538 | B29: 538 | C29: 2 | D29: 45925 | E29: Yes | F29: ZA-2022-DUVE-302 | G29: ZA-2020-OPDP-2190 | H29: 85 | I29: Yes | J29: =IF(A29="","",COUNTIF(RacePerformance!$F:$F,A29)) -> 0 | K29: =IF(A29="","",IFERROR(AVERAGEIF(RacePerformance!$F:$F,A29,RacePerformance!$I:$I),"")) | L29: =IF(A29="","",IFERROR(AVERAGEIF(RacePerformance!$F:$F,A29,RacePerformance!$J:$J),"")) | M29: =IF(A29="","",IFERROR(AVERAGEIF(RacePerformance!$F:$F,A29,RacePerformance!$K:$K),"")) | N29: =IF(A29="","",COUNTIFS(RacePerformance!$F:$F,A29,RacePerformance!$I:$I,"<=20")) -> 0 | O29: =IF(A29="","",COUNTIFS(RacePerformance!$F:$F,A29,RacePerformance!$I:$I,1)) -> 0 | P29: =IF(A29="","",COUNTIFS(RacePerformance!$F:$F,A29,RacePerformance!$J:$J,"<=3")) -> 0
A30: ZA-2025-DUVE-548 | B30: 548 | C30: 3 | D30: 45945 | E30: Yes | F30: ZA-2022-DUVE-302 | G30: ZA-2020-OPDP-2190 | H30: 85 | I30: Yes | J30: =IF(A30="","",COUNTIF(RacePerformance!$F:$F,A30)) -> 2 | K30: =IF(A30="","",IFERROR(AVERAGEIF(RacePerformance!$F:$F,A30,RacePerformance!$I:$I),"")) -> 80.5 | L30: =IF(A30="","",IFERROR(AVERAGEIF(RacePerformance!$F:$F,A30,RacePerformance!$J:$J),"")) -> 7.5 | M30: =IF(A30="","",IFERROR(AVERAGEIF(RacePerformance!$F:$F,A30,RacePerformance!$K:$K),"")) -> 0.5283208 | N30: =IF(A30="","",COUNTIFS(RacePerformance!$F:$F,A30,RacePerformance!$I:$I,"<=20")) -> 0 | O30: =IF(A30="","",COUNTIFS(RacePerformance!$F:$F,A30,RacePerformance!$I:$I,1)) -> 0 | P30: =IF(A30="","",COUNTIFS(RacePerformance!$F:$F,A30,RacePerformance!$J:$J,"<=3")) -> 0
A31: ZA-2025-DUVE-558 | B31: 558 | C31: 3 | D31: 45945 | E31: Yes | F31: ZA-2022-DUVE-302 | G31: ZA-2020-OPDP-2190 | H31: 90 | I31: Yes | J31: =IF(A31="","",COUNTIF(RacePerformance!$F:$F,A31)) -> 1 | K31: =IF(A31="","",IFERROR(AVERAGEIF(RacePerformance!$F:$F,A31,RacePerformance!$I:$I),"")) -> 89 | L31: =IF(A31="","",IFERROR(AVERAGEIF(RacePerformance!$F:$F,A31,RacePerformance!$J:$J),"")) -> 11 | M31: =IF(A31="","",IFERROR(AVERAGEIF(RacePerformance!$F:$F,A31,RacePerformance!$K:$K),"")) -> 0.3358396 | N31: =IF(A31="","",COUNTIFS(RacePerformance!$F:$F,A31,RacePerformance!$I:$I,"<=20")) -> 0 | O31: =IF(A31="","",COUNTIFS(RacePerformance!$F:$F,A31,RacePerformance!$I:$I,1)) -> 0 | P31: =IF(A31="","",COUNTIFS(RacePerformance!$F:$F,A31,RacePerformance!$J:$J,"<=3")) -> 0
A32: ZA-2025-DUVE-578 | B32: 578 | C32: 4 | D32: 45983 | E32: Yes | F32: ZA-2022-DUVE-302 | G32: ZA-2022-DUVE-243 | H32: 75 | I32: Yes | J32: =IF(A32="","",COUNTIF(RacePerformance!$F:$F,A32)) -> 1 | K32: =IF(A32="","",IFERROR(AVERAGEIF(RacePerformance!$F:$F,A32,RacePerformance!$I:$I),"")) -> 53 | L32: =IF(A32="","",IFERROR(AVERAGEIF(RacePerformance!$F:$F,A32,RacePerformance!$J:$J),"")) -> 6 | M32: =IF(A32="","",IFERROR(AVERAGEIF(RacePerformance!$F:$F,A32,RacePerformance!$K:$K),"")) -> 0.63784461 | N32: =IF(A32="","",COUNTIFS(RacePerformance!$F:$F,A32,RacePerformance!$I:$I,"<=20")) -> 0 | O32: =IF(A32="","",COUNTIFS(RacePerformance!$F:$F,A32,RacePerformance!$I:$I,1)) -> 0 | P32: =IF(A32="","",COUNTIFS(RacePerformance!$F:$F,A32,RacePerformance!$J:$J,"<=3")) -> 0
A33: ZA-2025-DUVE-568 | B33: 568 | C33: 4 | D33: 45983 | E33: Yes | F33: ZA-2022-DUVE-302 | G33: ZA-2022-DUVE-243 | H33: 75 | I33: No | J33: =IF(A33="","",COUNTIF(RacePerformance!$F:$F,A33)) -> 0 | K33: =IF(A33="","",IFERROR(AVERAGEIF(RacePerformance!$F:$F,A33,RacePerformance!$I:$I),"")) | L33: =IF(A33="","",IFERROR(AVERAGEIF(RacePerformance!$F:$F,A33,RacePerformance!$J:$J),"")) | M33: =IF(A33="","",IFERROR(AVERAGEIF(RacePerformance!$F:$F,A33,RacePerformance!$K:$K),"")) | N33: =IF(A33="","",COUNTIFS(RacePerformance!$F:$F,A33,RacePerformance!$I:$I,"<=20")) -> 0 | O33: =IF(A33="","",COUNTIFS(RacePerformance!$F:$F,A33,RacePerformance!$I:$I,1)) -> 0 | P33: =IF(A33="","",COUNTIFS(RacePerformance!$F:$F,A33,RacePerformance!$J:$J,"<=3")) -> 0
A34: ZA-2025-DUVE-520 | B34: 520 | C34: 3 | D34: 45962 | E34: Yes | F34: ZA-2022-GRP-029 | G34: ZA-2019-OP-9331 | H34: 75 | I34: Yes | J34: =IF(A34="","",COUNTIF(RacePerformance!$F:$F,A34)) -> 0 | K34: =IF(A34="","",IFERROR(AVERAGEIF(RacePerformance!$F:$F,A34,RacePerformance!$I:$I),"")) | L34: =IF(A34="","",IFERROR(AVERAGEIF(RacePerformance!$F:$F,A34,RacePerformance!$J:$J),"")) | M34: =IF(A34="","",IFERROR(AVERAGEIF(RacePerformance!$F:$F,A34,RacePerformance!$K:$K),"")) | N34: =IF(A34="","",COUNTIFS(RacePerformance!$F:$F,A34,RacePerformance!$I:$I,"<=20")) -> 0 | O34: =IF(A34="","",COUNTIFS(RacePerformance!$F:$F,A34,RacePerformance!$I:$I,1)) -> 0 | P34: =IF(A34="","",COUNTIFS(RacePerformance!$F:$F,A34,RacePerformance!$J:$J,"<=3")) -> 0
A35: ZA-2025-DUVE-530 | B35: 530 | C35: 1 | D35: 45967 | F35: ZA-2024-DUVENAGE-425 | G35: ZA-2020-OPDP-2190 | H35: 75 | I35: Yes | J35: =IF(A35="","",COUNTIF(RacePerformance!$F:$F,A35)) -> 2 | K35: =IF(A35="","",IFERROR(AVERAGEIF(RacePerformance!$F:$F,A35,RacePerformance!$I:$I),"")) -> 104.5 | L35: =IF(A35="","",IFERROR(AVERAGEIF(RacePerformance!$F:$F,A35,RacePerformance!$J:$J),"")) -> 11 | M35: =IF(A35="","",IFERROR(AVERAGEIF(RacePerformance!$F:$F,A35,RacePerformance!$K:$K),"")) -> 0.31091315 | N35: =IF(A35="","",COUNTIFS(RacePerformance!$F:$F,A35,RacePerformance!$I:$I,"<=20")) -> 0 | O35: =IF(A35="","",COUNTIFS(RacePerformance!$F:$F,A35,RacePerformance!$I:$I,1)) -> 0 | P35: =IF(A35="","",COUNTIFS(RacePerformance!$F:$F,A35,RacePerformance!$J:$J,"<=3")) -> 0
A36: ZA-2025-DUVE-540 | B36: 540 | C36: 1 | D36: 45967 | F36: ZA-2024-DUVENAGE-425 | G36: ZA-2020-OPDP-2190 | H36: 80 | I36: Yes | J36: =IF(A36="","",COUNTIF(RacePerformance!$F:$F,A36)) -> 1 | K36: =IF(A36="","",IFERROR(AVERAGEIF(RacePerformance!$F:$F,A36,RacePerformance!$I:$I),"")) -> 112 | L36: =IF(A36="","",IFERROR(AVERAGEIF(RacePerformance!$F:$F,A36,RacePerformance!$J:$J),"")) -> 12 | M36: =IF(A36="","",IFERROR(AVERAGEIF(RacePerformance!$F:$F,A36,RacePerformance!$K:$K),"")) -> 0.28861284 | N36: =IF(A36="","",COUNTIFS(RacePerformance!$F:$F,A36,RacePerformance!$I:$I,"<=20")) -> 0 | O36: =IF(A36="","",COUNTIFS(RacePerformance!$F:$F,A36,RacePerformance!$I:$I,1)) -> 0 | P36: =IF(A36="","",COUNTIFS(RacePerformance!$F:$F,A36,RacePerformance!$J:$J,"<=3")) -> 0
A37: ZA-2025-DUVE-510 | B37: 510 | C37: 2 | D37: 45954 | E37: Yes | F37: ZA-2024-GAMTOOS-233 | G37: ZA-2022-DUVE-243 | H37: 85 | I37: No | J37: =IF(A37="","",COUNTIF(RacePerformance!$F:$F,A37)) -> 0 | K37: =IF(A37="","",IFERROR(AVERAGEIF(RacePerformance!$F:$F,A37,RacePerformance!$I:$I),"")) | L37: =IF(A37="","",IFERROR(AVERAGEIF(RacePerformance!$F:$F,A37,RacePerformance!$J:$J),"")) | M37: =IF(A37="","",IFERROR(AVERAGEIF(RacePerformance!$F:$F,A37,RacePerformance!$K:$K),"")) | N37: =IF(A37="","",COUNTIFS(RacePerformance!$F:$F,A37,RacePerformance!$I:$I,"<=20")) -> 0 | O37: =IF(A37="","",COUNTIFS(RacePerformance!$F:$F,A37,RacePerformance!$I:$I,1)) -> 0 | P37: =IF(A37="","",COUNTIFS(RacePerformance!$F:$F,A37,RacePerformance!$J:$J,"<=3")) -> 0
A38: ZA-2025-DUVE-550 | B38: 550 | C38: 1 | D38: 45984 | F38: ZA-2024-GAMTOOS-233 | G38: ZA-2019-OP-9331 | H38: 75 | I38: No | J38: =IF(A38="","",COUNTIF(RacePerformance!$F:$F,A38)) -> 0 | K38: =IF(A38="","",IFERROR(AVERAGEIF(RacePerformance!$F:$F,A38,RacePerformance!$I:$I),"")) | L38: =IF(A38="","",IFERROR(AVERAGEIF(RacePerformance!$F:$F,A38,RacePerformance!$J:$J),"")) | M38: =IF(A38="","",IFERROR(AVERAGEIF(RacePerformance!$F:$F,A38,RacePerformance!$K:$K),"")) | N38: =IF(A38="","",COUNTIFS(RacePerformance!$F:$F,A38,RacePerformance!$I:$I,"<=20")) -> 0 | O38: =IF(A38="","",COUNTIFS(RacePerformance!$F:$F,A38,RacePerformance!$I:$I,1)) -> 0 | P38: =IF(A38="","",COUNTIFS(RacePerformance!$F:$F,A38,RacePerformance!$J:$J,"<=3")) -> 0
A39: ZA-2025-DUVE-560 | B39: 560 | C39: 1 | D39: 45984 | F39: ZA-2024-GAMTOOS-233 | G39: ZA-2019-OP-9331 | H39: 75 | I39: Yes | J39: =IF(A39="","",COUNTIF(RacePerformance!$F:$F,A39)) -> 0 | K39: =IF(A39="","",IFERROR(AVERAGEIF(RacePerformance!$F:$F,A39,RacePerformance!$I:$I),"")) | L39: =IF(A39="","",IFERROR(AVERAGEIF(RacePerformance!$F:$F,A39,RacePerformance!$J:$J),"")) | M39: =IF(A39="","",IFERROR(AVERAGEIF(RacePerformance!$F:$F,A39,RacePerformance!$K:$K),"")) | N39: =IF(A39="","",COUNTIFS(RacePerformance!$F:$F,A39,RacePerformance!$I:$I,"<=20")) -> 0 | O39: =IF(A39="","",COUNTIFS(RacePerformance!$F:$F,A39,RacePerformance!$I:$I,1)) -> 0 | P39: =IF(A39="","",COUNTIFS(RacePerformance!$F:$F,A39,RacePerformance!$J:$J,"<=3")) -> 0
J40: =IF(A40="","",COUNTIF(RacePerformance!$F:$F,A40)) | K40: =IF(A40="","",IFERROR(AVERAGEIF(RacePerformance!$F:$F,A40,RacePerformance!$I:$I),"")) | L40: =IF(A40="","",IFERROR(AVERAGEIF(RacePerformance!$F:$F,A40,RacePerformance!$J:$J),"")) | M40: =IF(A40="","",IFERROR(AVERAGEIF(RacePerformance!$F:$F,A40,RacePerformance!$K:$K),"")) | N40: =IF(A40="","",COUNTIFS(RacePerformance!$F:$F,A40,RacePerformance!$I:$I,"<=20")) | O40: =IF(A40="","",COUNTIFS(RacePerformance!$F:$F,A40,RacePerformance!$I:$I,1)) | P40: =IF(A40="","",COUNTIFS(RacePerformance!$F:$F,A40,RacePerformance!$J:$J,"<=3"))
...

Sheet Cocks
A1: CockID | B1: Name | C1: GENDER | D1: Pre-Season Rank | E1: STATUS | F1: TotalChicksBred | G1: InLoftsSeasonStart | H1: ChicksTotalRaces | I1: ChicksNotInLoft | J1: BreedingIndex | K1: Top20FedFinishes | L1: FedWins | M1: Loft top 3 | N1: Ranking | O1: InLoftsSeasonStart
A2: 28732 | D2: =IFERROR(AVERAGEIF(Chicks!$F:$F, $A2, Chicks!$H:$H), "") | F2: =IF(A2="","",COUNTIF(Chicks!$F:$F,A2)) -> 0 | G2: =IF(A2="","",COUNTIFS(Chicks!$F:$F,A2,Chicks!$I:$I,"Yes")) -> 0 | H2: =IF(A2="","",SUMIFS(Chicks!$J:$J,Chicks!$F:$F,A2)) -> 0 | I2: =IF(A2="","",COUNTIFS(Chicks!$F:$F,A2,Chicks!$I:$I,"No")) -> 0 | J2: =IF(A2="","",IFERROR(AVERAGEIF(Chicks!$F:$F,A2,Chicks!$M:$M),"")) | K2: =IF(A2="","",SUMIFS(Chicks!$N:$N,Chicks!$F:$F,A2)) -> 0 | L2: =IF(A2="","",SUMIFS(Chicks!$O:$O,Chicks!$F:$F,A2)) -> 0 | M2: =IF(A2="","",SUMIFS(Chicks!$P:$P,Chicks!$F:$F,A2)) -> 0 | N2: =IF($J2="","",RANK($J2,$J$2:$J$997,0))
A3: 129 | D3: =IFERROR(AVERAGEIF(Chicks!$F:$F, $A3, Chicks!$H:$H), "") | F3: =IF(A3="","",COUNTIF(Chicks!$F:$F,A3)) -> 0 | G3: =IF(A3="","",COUNTIFS(Chicks!$F:$F,A3,Chicks!$I:$I,"Yes")) -> 0 | H3: =IF(A3="","",SUMIFS(Chicks!$J:$J,Chicks!$F:$F,A3)) -> 0 | I3: =IF(A3="","",COUNTIFS(Chicks!$F:$F,A3,Chicks!$I:$I,"No")) -> 0 | J3: =IF(A3="","",IFERROR(AVERAGEIF(Chicks!$F:$F,A3,Chicks!$M:$M),"")) | K3: =IF(A3="","",SUMIFS(Chicks!$N:$N,Chicks!$F:$F,A3)) -> 0 | L3: =IF(A3="","",SUMIFS(Chicks!$O:$O,Chicks!$F:$F,A3)) -> 0 | M3: =IF(A3="","",SUMIFS(Chicks!$P:$P,Chicks!$F:$F,A3)) -> 0 | N3: =IF($J3="","",RANK($J3,$J$2:$J$997,0))
A4: 304 | D4: =IFERROR(AVERAGEIF(Chicks!$F:$F, $A4, Chicks!$H:$H), "") | F4: =IF(A4="","",COUNTIF(Chicks!$F:$F,A4)) -> 0 | G4: =IF(A4="","",COUNTIFS(Chicks!$F:$F,A4,Chicks!$I:$I,"Yes")) -> 0 | H4: =IF(A4="","",SUMIFS(Chicks!$J:$J,Chicks!$F:$F,A4)) -> 0 | I4: =IF(A4="","",COUNTIFS(Chicks!$F:$F,A4,Chicks!$I:$I,"No")) -> 0 | J4: =IF(A4="","",IFERROR(AVERAGEIF(Chicks!$F:$F,A4,Chicks!$M:$M),"")) | K4: =IF(A4="","",SUMIFS(Chicks!$N:$N,Chicks!$F:$F,A4)) -> 0 | L4: =IF(A4="","",SUMIFS(Chicks!$O:$O,Chicks!$F:$F,A4)) -> 0 | M4: =IF(A4="","",SUMIFS(Chicks!$P:$P,Chicks!$F:$F,A4)) -> 0 | N4: =IF($J4="","",RANK($J4,$J$2:$J$997,0))
A5: 58 | D5: =IFERROR(AVERAGEIF(Chicks!$F:$F, $A5, Chicks!$H:$H), "") | F5: =IF(A5="","",COUNTIF(Chicks!$F:$F,A5)) -> 0 | G5: =IF(A5="","",COUNTIFS(Chicks!$F:$F,A5,Chicks!$I:$I,"Yes")) -> 0 | H5: =IF(A5="","",SUMIFS(Chicks!$J:$J,Chicks!$F:$F,A5)) -> 0 | I5: =IF(A5="","",COUNTIFS(Chicks!$F:$F,A5,Chicks!$I:$I,"No")) -> 0 | J5: =IF(A5="","",IFERROR(AVERAGEIF(Chicks!$F:$F,A5,Chicks!$M:$M),"")) | K5: =IF(A5="","",SUMIFS(Chicks!$N:$N,Chicks!$F:$F,A5)) -> 0 | L5: =IF(A5="","",SUMIFS(Chicks!$O:$O,Chicks!$F:$F,A5)) -> 0 | M5: =IF(A5="","",SUMIFS(Chicks!$P:$P,Chicks!$F:$F,A5)) -> 0 | N5: =IF($J5="","",RANK($J5,$J$2:$J$997,0))
A6: ZA-2022-DUVE-241 | B6: 241 | C6: COCK | D6: =IFERROR(AVERAGEIF(Chicks!$F:$F, $A6, Chicks!$H:$H), "") -> 84.166667 | E6: ACTIVE | F6: =IF(A6="","",COUNTIF(Chicks!$F:$F,A6)) -> 6 | G6: =IF(A6="","",COUNTIFS(Chicks!$F:$F,A6,Chicks!$I:$I,"Yes")) -> 5 | H6: =IF(A6="","",SUMIFS(Chicks!$J:$J,Chicks!$F:$F,A6)) -> 2 | I6: =IF(A6="","",COUNTIFS(Chicks!$F:$F,A6,Chicks!$I:$I,"No")) -> 1 | J6: =IF(A6="","",IFERROR(AVERAGEIF(Chicks!$F:$F,A6,Chicks!$M:$M),"")) -> 0.3998202 | K6: =IF(A6="","",SUMIFS(Chicks!$N:$N,Chicks!$F:$F,A6)) -> 0 | L6: =IF(A6="","",SUMIFS(Chicks!$O:$O,Chicks!$F:$F,A6)) -> 0 | M6: =IF(A6="","",SUMIFS(Chicks!$P:$P,Chicks!$F:$F,A6)) -> 0 | N6: =IF($J6="","",RANK($J6,$J$2:$J$997,0)) -> 5 | O6: =SUM(G6/F6) -> 0.83333333
A7: ZA-2022-DUVE-302 | B7: 302 | C7: COCK | D7: =IFERROR(AVERAGEIF(Chicks!$F:$F, $A7, Chicks!$H:$H), "") -> 83.75 | E7: ACTIVE | F7: =IF(A7="","",COUNTIF(Chicks!$F:$F,A7)) -> 8 | G7: =IF(A7="","",COUNTIFS(Chicks!$F:$F,A7,Chicks!$I:$I,"Yes")) -> 5 | H7: =IF(A7="","",SUMIFS(Chicks!$J:$J,Chicks!$F:$F,A7)) -> 4 | I7: =IF(A7="","",COUNTIFS(Chicks!$F:$F,A7,Chicks!$I:$I,"No")) -> 3 | J7: =IF(A7="","",IFERROR(AVERAGEIF(Chicks!$F:$F,A7,Chicks!$M:$M),"")) -> 0.50066834 | K7: =IF(A7="","",SUMIFS(Chicks!$N:$N,Chicks!$F:$F,A7)) -> 0 | L7: =IF(A7="","",SUMIFS(Chicks!$O:$O,Chicks!$F:$F,A7)) -> 0 | M7: =IF(A7="","",SUMIFS(Chicks!$P:$P,Chicks!$F:$F,A7)) -> 0 | N7: =IF($J7="","",RANK($J7,$J$2:$J$997,0)) -> 4 | O7: =SUM(G7/F7) -> 0.625
A8: ZA-2022-DUVE-240 | B8: 240 | C8: COCK | D8: =IFERROR(AVERAGEIF(Chicks!$F:$F, $A8, Chicks!$H:$H), "") -> 82.5 | E8: ACTIVE | F8: =IF(A8="","",COUNTIF(Chicks!$F:$F,A8)) -> 3 | G8: =IF(A8="","",COUNTIFS(Chicks!$F:$F,A8,Chicks!$I:$I,"Yes")) -> 1 | H8: =IF(A8="","",SUMIFS(Chicks!$J:$J,Chicks!$F:$F,A8)) -> 0 | I8: =IF(A8="","",COUNTIFS(Chicks!$F:$F,A8,Chicks!$I:$I,"No")) -> 2 | J8: =IF(A8="","",IFERROR(AVERAGEIF(Chicks!$F:$F,A8,Chicks!$M:$M),"")) | K8: =IF(A8="","",SUMIFS(Chicks!$N:$N,Chicks!$F:$F,A8)) -> 0 | L8: =IF(A8="","",SUMIFS(Chicks!$O:$O,Chicks!$F:$F,A8)) -> 0 | M8: =IF(A8="","",SUMIFS(Chicks!$P:$P,Chicks!$F:$F,A8)) -> 0 | N8: =IF($J8="","",RANK($J8,$J$2:$J$997,0)) | O8: =SUM(G8/F8) -> 0.33333333
A9: ZA-2019-OPJB-251 | B9: 251 | C9: COCK | D9: =IFERROR(AVERAGEIF(Chicks!$F:$F, $A9, Chicks!$H:$H), "") -> 81 | E9: ACTIVE | F9: =IF(A9="","",COUNTIF(Chicks!$F:$F,A9)) -> 6 | G9: =IF(A9="","",COUNTIFS(Chicks!$F:$F,A9,Chicks!$I:$I,"Yes")) -> 3 | H9: =IF(A9="","",SUMIFS(Chicks!$J:$J,Chicks!$F:$F,A9)) -> 3 | I9: =IF(A9="","",COUNTIFS(Chicks!$F:$F,A9,Chicks!$I:$I,"No")) -> 3 | J9: =IF(A9="","",IFERROR(AVERAGEIF(Chicks!$F:$F,A9,Chicks!$M:$M),"")) -> 0.63230393 | K9: =IF(A9="","",SUMIFS(Chicks!$N:$N,Chicks!$F:$F,A9)) -> 0 | L9: =IF(A9="","",SUMIFS(Chicks!$O:$O,Chicks!$F:$F,A9)) -> 0 | M9: =IF(A9="","",SUMIFS(Chicks!$P:$P,Chicks!$F:$F,A9)) -> 1 | N9: =IF($J9="","",RANK($J9,$J$2:$J$997,0)) -> 2 | O9: =SUM(G9/F9) -> 0.5
A10: ZA-2020-OP-19773 | B10: 19773 | C10: COCK | D10: =IFERROR(AVERAGEIF(Chicks!$F:$F, $A10, Chicks!$H:$H), "") -> 80.714286 | E10: ACTIVE | F10: =IF(A10="","",COUNTIF(Chicks!$F:$F,A10)) -> 7 | G10: =IF(A10="","",COUNTIFS(Chicks!$F:$F,A10,Chicks!$I:$I,"Yes")) -> 1 | H10: =IF(A10="","",SUMIFS(Chicks!$J:$J,Chicks!$F:$F,A10)) -> 2 | I10: =IF(A10="","",COUNTIFS(Chicks!$F:$F,A10,Chicks!$I:$I,"No")) -> 6 | J10: =IF(A10="","",IFERROR(AVERAGEIF(Chicks!$F:$F,A10,Chicks!$M:$M),"")) -> 0.65702929 | K10: =IF(A10="","",SUMIFS(Chicks!$N:$N,Chicks!$F:$F,A10)) -> 1 | L10: =IF(A10="","",SUMIFS(Chicks!$O:$O,Chicks!$F:$F,A10)) -> 0 | M10: =IF(A10="","",SUMIFS(Chicks!$P:$P,Chicks!$F:$F,A10)) -> 1 | N10: =IF($J10="","",RANK($J10,$J$2:$J$997,0)) -> 1 | O10: =SUM(G10/F10) -> 0.14285714
A11: ZA-2024-GAMTOOS-233 | B11: 233 | C11: COCK | D11: =IFERROR(AVERAGEIF(Chicks!$F:$F, $A11, Chicks!$H:$H), "") -> 78.333333 | E11: ACTIVE | F11: =IF(A11="","",COUNTIF(Chicks!$F:$F,A11)) -> 3 | G11: =IF(A11="","",COUNTIFS(Chicks!$F:$F,A11,Chicks!$I:$I,"Yes")) -> 1 | H11: =IF(A11="","",SUMIFS(Chicks!$J:$J,Chicks!$F:$F,A11)) -> 0 | I11: =IF(A11="","",COUNTIFS(Chicks!$F:$F,A11,Chicks!$I:$I,"No")) -> 2 | J11: =IF(A11="","",IFERROR(AVERAGEIF(Chicks!$F:$F,A11,Chicks!$M:$M),"")) | K11: =IF(A11="","",SUMIFS(Chicks!$N:$N,Chicks!$F:$F,A11)) -> 0 | L11: =IF(A11="","",SUMIFS(Chicks!$O:$O,Chicks!$F:$F,A11)) -> 0 | M11: =IF(A11="","",SUMIFS(Chicks!$P:$P,Chicks!$F:$F,A11)) -> 0 | N11: =IF($J11="","",RANK($J11,$J$2:$J$997,0)) | O11: =SUM(G11/F11) -> 0.33333333
A12: ZA-2024-DUVENAGE-425 | B12: 425 | C12: COCK | D12: =IFERROR(AVERAGEIF(Chicks!$F:$F, $A12, Chicks!$H:$H), "") -> 77.5 | E12: ACTIVE | F12: =IF(A12="","",COUNTIF(Chicks!$F:$F,A12)) -> 2 | G12: =IF(A12="","",COUNTIFS(Chicks!$F:$F,A12,Chicks!$I:$I,"Yes")) -> 2 | H12: =IF(A12="","",SUMIFS(Chicks!$J:$J,Chicks!$F:$F,A12)) -> 3 | I12: =IF(A12="","",COUNTIFS(Chicks!$F:$F,A12,Chicks!$I:$I,"No")) -> 0 | J12: =IF(A12="","",IFERROR(AVERAGEIF(Chicks!$F:$F,A12,Chicks!$M:$M),"")) -> 0.29976299 | K12: =IF(A12="","",SUMIFS(Chicks!$N:$N,Chicks!$F:$F,A12)) -> 0 | L12: =IF(A12="","",SUMIFS(Chicks!$O:$O,Chicks!$F:$F,A12)) -> 0 | M12: =IF(A12="","",SUMIFS(Chicks!$P:$P,Chicks!$F:$F,A12)) -> 0 | N12: =IF($J12="","",RANK($J12,$J$2:$J$997,0)) -> 6 | O12: =SUM(G12/F12) -> 1
A13: ZA-2015-OP-7903 | B13: 7903 | C13: COCK | D13: =IFERROR(AVERAGEIF(Chicks!$F:$F, $A13, Chicks!$H:$H), "") -> 77.5 | E13: RITIRED | F13: =IF(A13="","",COUNTIF(Chicks!$F:$F,A13)) -> 2 | G13: =IF(A13="","",COUNTIFS(Chicks!$F:$F,A13,Chicks!$I:$I,"Yes")) -> 2 | H13: =IF(A13="","",SUMIFS(Chicks!$J:$J,Chicks!$F:$F,A13)) -> 2 | I13: =IF(A13="","",COUNTIFS(Chicks!$F:$F,A13,Chicks!$I:$I,"No")) -> 0 | J13: =IF(A13="","",IFERROR(AVERAGEIF(Chicks!$F:$F,A13,Chicks!$M:$M),"")) -> 0.57949766 | K13: =IF(A13="","",SUMIFS(Chicks!$N:$N,Chicks!$F:$F,A13)) -> 0 | L13: =IF(A13="","",SUMIFS(Chicks!$O:$O,Chicks!$F:$F,A13)) -> 0 | M13: =IF(A13="","",SUMIFS(Chicks!$P:$P,Chicks!$F:$F,A13)) -> 0 | N13: =IF($J13="","",RANK($J13,$J$2:$J$997,0)) -> 3 | O13: =SUM(G13/F13) -> 1
A14: ZA-2022-GRP-029 | B14: 29 | C14: COCK | D14: =IFERROR(AVERAGEIF(Chicks!$F:$F, $A14, Chicks!$H:$H), "") -> 75 | E14: ACTIVE | F14: =IF(A14="","",COUNTIF(Chicks!$F:$F,A14)) -> 1 | G14: =IF(A14="","",COUNTIFS(Chicks!$F:$F,A14,Chicks!$I:$I,"Yes")) -> 1 | H14: =IF(A14="","",SUMIFS(Chicks!$J:$J,Chicks!$F:$F,A14)) -> 0 | I14: =IF(A14="","",COUNTIFS(Chicks!$F:$F,A14,Chicks!$I:$I,"No")) -> 0 | J14: =IF(A14="","",IFERROR(AVERAGEIF(Chicks!$F:$F,A14,Chicks!$M:$M),"")) | K14: =IF(A14="","",SUMIFS(Chicks!$N:$N,Chicks!$F:$F,A14)) -> 0 | L14: =IF(A14="","",SUMIFS(Chicks!$O:$O,Chicks!$F:$F,A14)) -> 0 | M14: =IF(A14="","",SUMIFS(Chicks!$P:$P,Chicks!$F:$F,A14)) -> 0 | N14: =IF($J14="","",RANK($J14,$J$2:$J$997,0)) | O14: =SUM(G14/F14) -> 1
F15: =IF(A15="","",COUNTIF(Chicks!$F:$F,A15)) | G15: =IF(A15="","",COUNTIFS(Chicks!$F:$F,A15,Chicks!$I:$I,"Yes")) | H15: =IF(A15="","",SUMIFS(Chicks!$J:$J,Chicks!$F:$F,A15)) | I15: =IF(A15="","",COUNTIFS(Chicks!$F:$F,A15,Chicks!$I:$I,"No")) | J15: =IF(A15="","",IFERROR(AVERAGEIF(Chicks!$F:$F,A15,Chicks!$M:$M),"")) | K15: =IF(A15="","",SUMIFS(Chicks!$N:$N,Chicks!$F:$F,A15)) | L15: =IF(A15="","",SUMIFS(Chicks!$O:$O,Chicks!$F:$F,A15)) | M15: =IF(A15="","",SUMIFS(Chicks!$P:$P,Chicks!$F:$F,A15)) | N15: =IF($J15="","",RANK($J15,$J$2:$J$997,0))
F16: =IF(A16="","",COUNTIF(Chicks!$F:$F,A16)) | G16: =IF(A16="","",COUNTIFS(Chicks!$F:$F,A16,Chicks!$I:$I,"Yes")) | H16: =IF(A16="","",SUMIFS(Chicks!$J:$J,Chicks!$F:$F,A16)) | I16: =IF(A16="","",COUNTIFS(Chicks!$F:$F,A16,Chicks!$I:$I,"No")) | J16: =IF(A16="","",IFERROR(AVERAGEIF(Chicks!$F:$F,A16,Chicks!$M:$M),"")) | K16: =IF(A16="","",SUMIFS(Chicks!$N:$N,Chicks!$F:$F,A16)) | L16: =IF(A16="","",SUMIFS(Chicks!$O:$O,Chicks!$F:$F,A16)) | M16: =IF(A16="","",SUMIFS(Chicks!$P:$P,Chicks!$F:$F,A16)) | N16: =IF($J16="","",RANK($J16,$J$2:$J$997,0))
F17: =IF(A17="","",COUNTIF(Chicks!$F:$F,A17)) | G17: =IF(A17="","",COUNTIFS(Chicks!$F:$F,A17,Chicks!$I:$I,"Yes")) | H17: =IF(A17="","",SUMIFS(Chicks!$J:$J,Chicks!$F:$F,A17)) | I17: =IF(A17="","",COUNTIFS(Chicks!$F:$F,A17,Chicks!$I:$I,"No")) | J17: =IF(A17="","",IFERROR(AVERAGEIF(Chicks!$F:$F,A17,Chicks!$M:$M),"")) | K17: =IF(A17="","",SUMIFS(Chicks!$N:$N,Chicks!$F:$F,A17)) | L17: =IF(A17="","",SUMIFS(Chicks!$O:$O,Chicks!$F:$F,A17)) | M17: =IF(A17="","",SUMIFS(Chicks!$P:$P,Chicks!$F:$F,A17)) | N17: =IF($J17="","",RANK($J17,$J$2:$J$997,0))
F18: =IF(A18="","",COUNTIF(Chicks!$F:$F,A18)) | G18: =IF(A18="","",COUNTIFS(Chicks!$F:$F,A18,Chicks!$I:$I,"Yes")) | H18: =IF(A18="","",SUMIFS(Chicks!$J:$J,Chicks!$F:$F,A18)) | I18: =IF(A18="","",COUNTIFS(Chicks!$F:$F,A18,Chicks!$I:$I,"No")) | J18: =IF(A18="","",IFERROR(AVERAGEIF(Chicks!$F:$F,A18,Chicks!$M:$M),"")) | K18: =IF(A18="","",SUMIFS(Chicks!$N:$N,Chicks!$F:$F,A18)) | L18: =IF(A18="","",SUMIFS(Chicks!$O:$O,Chicks!$F:$F,A18)) | M18: =IF(A18="","",SUMIFS(Chicks!$P:$P,Chicks!$F:$F,A18)) | N18: =IF($J18="","",RANK($J18,$J$2:$J$997,0))
F19: =IF(A19="","",COUNTIF(Chicks!$F:$F,A19)) | G19: =IF(A19="","",COUNTIFS(Chicks!$F:$F,A19,Chicks!$I:$I,"Yes")) | H19: =IF(A19="","",SUMIFS(Chicks!$J:$J,Chicks!$F:$F,A19)) | I19: =IF(A19="","",COUNTIFS(Chicks!$F:$F,A19,Chicks!$I:$I,"No")) | J19: =IF(A19="","",IFERROR(AVERAGEIF(Chicks!$F:$F,A19,Chicks!$M:$M),"")) | K19: =IF(A19="","",SUMIFS(Chicks!$N:$N,Chicks!$F:$F,A19)) | L19: =IF(A19="","",SUMIFS(Chicks!$O:$O,Chicks!$F:$F,A19)) | M19: =IF(A19="","",SUMIFS(Chicks!$P:$P,Chicks!$F:$F,A19)) | N19: =IF($J19="","",RANK($J19,$J$2:$J$997,0))
F20: =IF(A20="","",COUNTIF(Chicks!$F:$F,A20)) | G20: =IF(A20="","",COUNTIFS(Chicks!$F:$F,A20,Chicks!$I:$I,"Yes")) | H20: =IF(A20="","",SUMIFS(Chicks!$J:$J,Chicks!$F:$F,A20)) | I20: =IF(A20="","",COUNTIFS(Chicks!$F:$F,A20,Chicks!$I:$I,"No")) | J20: =IF(A20="","",IFERROR(AVERAGEIF(Chicks!$F:$F,A20,Chicks!$M:$M),"")) | K20: =IF(A20="","",SUMIFS(Chicks!$N:$N,Chicks!$F:$F,A20)) | L20: =IF(A20="","",SUMIFS(Chicks!$O:$O,Chicks!$F:$F,A20)) | M20: =IF(A20="","",SUMIFS(Chicks!$P:$P,Chicks!$F:$F,A20)) | N20: =IF($J20="","",RANK($J20,$J$2:$J$997,0))
F21: =IF(A21="","",COUNTIF(Chicks!$F:$F,A21)) | G21: =IF(A21="","",COUNTIFS(Chicks!$F:$F,A21,Chicks!$I:$I,"Yes")) | H21: =IF(A21="","",SUMIFS(Chicks!$J:$J,Chicks!$F:$F,A21)) | I21: =IF(A21="","",COUNTIFS(Chicks!$F:$F,A21,Chicks!$I:$I,"No")) | J21: =IF(A21="","",IFERROR(AVERAGEIF(Chicks!$F:$F,A21,Chicks!$M:$M),"")) | K21: =IF(A21="","",SUMIFS(Chicks!$N:$N,Chicks!$F:$F,A21)) | L21: =IF(A21="","",SUMIFS(Chicks!$O:$O,Chicks!$F:$F,A21)) | M21: =IF(A21="","",SUMIFS(Chicks!$P:$P,Chicks!$F:$F,A21)) | N21: =IF($J21="","",RANK($J21,$J$2:$J$997,0))
F22: =IF(A22="","",COUNTIF(Chicks!$F:$F,A22)) | G22: =IF(A22="","",COUNTIFS(Chicks!$F:$F,A22,Chicks!$I:$I,"Yes")) | H22: =IF(A22="","",SUMIFS(Chicks!$J:$J,Chicks!$F:$F,A22)) | I22: =IF(A22="","",COUNTIFS(Chicks!$F:$F,A22,Chicks!$I:$I,"No")) | J22: =IF(A22="","",IFERROR(AVERAGEIF(Chicks!$F:$F,A22,Chicks!$M:$M),"")) | K22: =IF(A22="","",SUMIFS(Chicks!$N:$N,Chicks!$F:$F,A22)) | L22: =IF(A22="","",SUMIFS(Chicks!$O:$O,Chicks!$F:$F,A22)) | M22: =IF(A22="","",SUMIFS(Chicks!$P:$P,Chicks!$F:$F,A22)) | N22: =IF($J22="","",RANK($J22,$J$2:$J$997,0))
F23: =IF(A23="","",COUNTIF(Chicks!$F:$F,A23)) | G23: =IF(A23="","",COUNTIFS(Chicks!$F:$F,A23,Chicks!$I:$I,"Yes")) | H23: =IF(A23="","",SUMIFS(Chicks!$J:$J,Chicks!$F:$F,A23)) | I23: =IF(A23="","",COUNTIFS(Chicks!$F:$F,A23,Chicks!$I:$I,"No")) | J23: =IF(A23="","",IFERROR(AVERAGEIF(Chicks!$F:$F,A23,Chicks!$M:$M),"")) | K23: =IF(A23="","",SUMIFS(Chicks!$N:$N,Chicks!$F:$F,A23)) | L23: =IF(A23="","",SUMIFS(Chicks!$O:$O,Chicks!$F:$F,A23)) | M23: =IF(A23="","",SUMIFS(Chicks!$P:$P,Chicks!$F:$F,A23)) | N23: =IF($J23="","",RANK($J23,$J$2:$J$997,0))
F24: =IF(A24="","",COUNTIF(Chicks!$F:$F,A24)) | G24: =IF(A24="","",COUNTIFS(Chicks!$F:$F,A24,Chicks!$I:$I,"Yes")) | H24: =IF(A24="","",SUMIFS(Chicks!$J:$J,Chicks!$F:$F,A24)) | I24: =IF(A24="","",COUNTIFS(Chicks!$F:$F,A24,Chicks!$I:$I,"No")) | J24: =IF(A24="","",IFERROR(AVERAGEIF(Chicks!$F:$F,A24,Chicks!$M:$M),"")) | K24: =IF(A24="","",SUMIFS(Chicks!$N:$N,Chicks!$F:$F,A24)) | L24: =IF(A24="","",SUMIFS(Chicks!$O:$O,Chicks!$F:$F,A24)) | M24: =IF(A24="","",SUMIFS(Chicks!$P:$P,Chicks!$F:$F,A24)) | N24: =IF($J24="","",RANK($J24,$J$2:$J$997,0))
F25: =IF(A25="","",COUNTIF(Chicks!$F:$F,A25)) | G25: =IF(A25="","",COUNTIFS(Chicks!$F:$F,A25,Chicks!$I:$I,"Yes")) | H25: =IF(A25="","",SUMIFS(Chicks!$J:$J,Chicks!$F:$F,A25)) | I25: =IF(A25="","",COUNTIFS(Chicks!$F:$F,A25,Chicks!$I:$I,"No")) | J25: =IF(A25="","",IFERROR(AVERAGEIF(Chicks!$F:$F,A25,Chicks!$M:$M),"")) | K25: =IF(A25="","",SUMIFS(Chicks!$N:$N,Chicks!$F:$F,A25)) | L25: =IF(A25="","",SUMIFS(Chicks!$O:$O,Chicks!$F:$F,A25)) | M25: =IF(A25="","",SUMIFS(Chicks!$P:$P,Chicks!$F:$F,A25)) | N25: =IF($J25="","",RANK($J25,$J$2:$J$997,0))
F26: =IF(A26="","",COUNTIF(Chicks!$F:$F,A26)) | G26: =IF(A26="","",COUNTIFS(Chicks!$F:$F,A26,Chicks!$I:$I,"Yes")) | H26: =IF(A26="","",SUMIFS(Chicks!$J:$J,Chicks!$F:$F,A26)) | I26: =IF(A26="","",COUNTIFS(Chicks!$F:$F,A26,Chicks!$I:$I,"No")) | J26: =IF(A26="","",IFERROR(AVERAGEIF(Chicks!$F:$F,A26,Chicks!$M:$M),"")) | K26: =IF(A26="","",SUMIFS(Chicks!$N:$N,Chicks!$F:$F,A26)) | L26: =IF(A26="","",SUMIFS(Chicks!$O:$O,Chicks!$F:$F,A26)) | M26: =IF(A26="","",SUMIFS(Chicks!$P:$P,Chicks!$F:$F,A26)) | N26: =IF($J26="","",RANK($J26,$J$2:$J$997,0))
... F997: =IF(A997="","",COUNTIF(Chicks!$F:$F,A997)) | G997: =IF(A997="","",COUNTIFS(Chicks!$F:$F,A997,Chicks!$I:$I,"Yes")) | H997: =IF(A997="","",SUMIFS(Chicks!$J:$J,Chicks!$F:$F,A997)) | I997: =IF(A997="","",COUNTIFS(Chicks!$F:$F,A997,Chicks!$I:$I,"No")) | J997: =IF(A997="","",IFERROR(AVERAGEIF(Chicks!$F:$F,A997,Chicks!$M:$M),"")) | K997: =IF(A997="","",SUMIFS(Chicks!$N:$N,Chicks!$F:$F,A997)) | L997: =IF(A997="","",SUMIFS(Chicks!$O:$O,Chicks!$F:$F,A997)) | M997: =IF(A997="","",SUMIFS(Chicks!$P:$P,Chicks!$F:$F,A997)) | N997: =IF($J997="","",RANK($J997,$J$2:$J$997,0))

Sheet Hens
A1: HenID | B1: Name | C1: GENDER | D1: Pre-Season Rank | E1: STATUS | F1: TotalChicksBred | G1: InLoftsSeasonStart | H1: ChicksTotalRaces | I1: ChicksNotInLoft | J1: BreedingIndex | K1: Top20FedFinishes | L1: FedWins | M1: Loft top 3 | N1: Ranking | O1: InLoftsSeasonStart
A2: ZA-2015-MEDPET-624 | B2: 624 | C2: HEN | D2: =IFERROR(AVERAGEIF(Chicks!$G:$G, $A2, Chicks!$H:$H), "") | E2: ACTIVE | F2: =IF(A2="","",COUNTIF(Chicks!$G:$G,A2)) -> 0 | G2: =IF(A2="","",COUNTIFS(Chicks!$G:$G,A2,Chicks!$I:$I,"Yes")) -> 0 | H2: =IF(A2="","",SUMIFS(Chicks!$J:$J,Chicks!$G:$G,A2)) -> 0 | I2: =IF(A2="","",COUNTIFS(Chicks!$G:$G,A2,Chicks!$I:$I,"No")) -> 0 | J2: =IF(A2="","",IFERROR(AVERAGEIF(Chicks!$G:$G,A2,Chicks!$M:$M),"")) | K2: =IF(A2="","",SUMIFS(Chicks!$N:$N,Chicks!$G:$G,A2)) -> 0 | L2: =IF(A2="","",SUMIFS(Chicks!$O:$O,Chicks!$G:$G,A2)) -> 0 | M2: =IF(A2="","",SUMIFS(Chicks!$P:$P,Chicks!$G:$G,A2)) -> 0 | N2: =IF($J2="","",RANK($J2,$J$2:$J$998,0)) | O2: =SUM(G2/F2) -> #DIV/0!
A3: ZA-2013-FB-19578 | B3: 19578 | C3: HEN | D3: =IFERROR(AVERAGEIF(Chicks!$G:$G, $A3, Chicks!$H:$H), "") | E3: RETIRED | F3: =IF(A3="","",COUNTIF(Chicks!$G:$G,A3)) -> 0 | G3: =IF(A3="","",COUNTIFS(Chicks!$G:$G,A3,Chicks!$I:$I,"Yes")) -> 0 | H3: =IF(A3="","",SUMIFS(Chicks!$J:$J,Chicks!$G:$G,A3)) -> 0 | I3: =IF(A3="","",COUNTIFS(Chicks!$G:$G,A3,Chicks!$I:$I,"No")) -> 0 | J3: =IF(A3="","",IFERROR(AVERAGEIF(Chicks!$G:$G,A3,Chicks!$M:$M),"")) | K3: =IF(A3="","",SUMIFS(Chicks!$N:$N,Chicks!$G:$G,A3)) -> 0 | L3: =IF(A3="","",SUMIFS(Chicks!$O:$O,Chicks!$G:$G,A3)) -> 0 | M3: =IF(A3="","",SUMIFS(Chicks!$P:$P,Chicks!$G:$G,A3)) -> 0 | N3: =IF($J3="","",RANK($J3,$J$2:$J$998,0)) | O3: =SUM(G3/F3) -> #DIV/0!
A4: ZA-2015-MEDPET-7060 | B4: 7060 | C4: HEN | D4: =IFERROR(AVERAGEIF(Chicks!$G:$G, $A4, Chicks!$H:$H), "") | E4: SOLD | F4: =IF(A4="","",COUNTIF(Chicks!$G:$G,A4)) -> 0 | G4: =IF(A4="","",COUNTIFS(Chicks!$G:$G,A4,Chicks!$I:$I,"Yes")) -> 0 | H4: =IF(A4="","",SUMIFS(Chicks!$J:$J,Chicks!$G:$G,A4)) -> 0 | I4: =IF(A4="","",COUNTIFS(Chicks!$G:$G,A4,Chicks!$I:$I,"No")) -> 0 | J4: =IF(A4="","",IFERROR(AVERAGEIF(Chicks!$G:$G,A4,Chicks!$M:$M),"")) | K4: =IF(A4="","",SUMIFS(Chicks!$N:$N,Chicks!$G:$G,A4)) -> 0 | L4: =IF(A4="","",SUMIFS(Chicks!$O:$O,Chicks!$G:$G,A4)) -> 0 | M4: =IF(A4="","",SUMIFS(Chicks!$P:$P,Chicks!$G:$G,A4)) -> 0 | N4: =IF($J4="","",RANK($J4,$J$2:$J$998,0)) | O4: =SUM(G4/F4) -> #DIV/0!
A5: ZA-2020-OP-19774 | B5: 19774 | C5: HEN | D5: =IFERROR(AVERAGEIF(Chicks!$G:$G, $A5, Chicks!$H:$H), "") | E5: ACTIVE | F5: =IF(A5="","",COUNTIF(Chicks!$G:$G,A5)) -> 0 | G5: =IF(A5="","",COUNTIFS(Chicks!$G:$G,A5,Chicks!$I:$I,"Yes")) -> 0 | H5: =IF(A5="","",SUMIFS(Chicks!$J:$J,Chicks!$G:$G,A5)) -> 0 | I5: =IF(A5="","",COUNTIFS(Chicks!$G:$G,A5,Chicks!$I:$I,"No")) -> 0 | J5: =IF(A5="","",IFERROR(AVERAGEIF(Chicks!$G:$G,A5,Chicks!$M:$M),"")) | K5: =IF(A5="","",SUMIFS(Chicks!$N:$N,Chicks!$G:$G,A5)) -> 0 | L5: =IF(A5="","",SUMIFS(Chicks!$O:$O,Chicks!$G:$G,A5)) -> 0 | M5: =IF(A5="","",SUMIFS(Chicks!$P:$P,Chicks!$G:$G,A5)) -> 0 | N5: =IF($J5="","",RANK($J5,$J$2:$J$998,0)) | O5: =SUM(G5/F5) -> #DIV/0!
A6: ZA-2020-OPDP-2190 | B6: 2190 | C6: HEN | D6: =IFERROR(AVERAGEIF(Chicks!$G:$G, $A6, Chicks!$H:$H), "") -> 84.375 | E6: ACTIVE | F6: =IF(A6="","",COUNTIF(Chicks!$G:$G,A6)) -> 8 | G6: =IF(A6="","",COUNTIFS(Chicks!$G:$G,A6,Chicks!$I:$I,"Yes")) -> 6 | H6: =IF(A6="","",SUMIFS(Chicks!$J:$J,Chicks!$G:$G,A6)) -> 6 | I6: =IF(A6="","",COUNTIFS(Chicks!$G:$G,A6,Chicks!$I:$I,"No")) -> 2 | J6: =IF(A6="","",IFERROR(AVERAGEIF(Chicks!$G:$G,A6,Chicks!$M:$M),"")) -> 0.3659216 | K6: =IF(A6="","",SUMIFS(Chicks!$N:$N,Chicks!$G:$G,A6)) -> 0 | L6: =IF(A6="","",SUMIFS(Chicks!$O:$O,Chicks!$G:$G,A6)) -> 0 | M6: =IF(A6="","",SUMIFS(Chicks!$P:$P,Chicks!$G:$G,A6)) -> 0 | N6: =IF($J6="","",RANK($J6,$J$2:$J$998,0)) -> 6 | O6: =SUM(G6/F6) -> 0.75
A7: ZA-2022-DUVE-233 | B7: 233 | C7: HEN | D7: =IFERROR(AVERAGEIF(Chicks!$G:$G, $A7, Chicks!$H:$H), "") -> 84.166667 | E7: ACTIVE | F7: =IF(A7="","",COUNTIF(Chicks!$G:$G,A7)) -> 6 | G7: =IF(A7="","",COUNTIFS(Chicks!$G:$G,A7,Chicks!$I:$I,"Yes")) -> 5 | H7: =IF(A7="","",SUMIFS(Chicks!$J:$J,Chicks!$G:$G,A7)) -> 2 | I7: =IF(A7="","",COUNTIFS(Chicks!$G:$G,A7,Chicks!$I:$I,"No")) -> 1 | J7: =IF(A7="","",IFERROR(AVERAGEIF(Chicks!$G:$G,A7,Chicks!$M:$M),"")) -> 0.3998202 | K7: =IF(A7="","",SUMIFS(Chicks!$N:$N,Chicks!$G:$G,A7)) -> 0 | L7: =IF(A7="","",SUMIFS(Chicks!$O:$O,Chicks!$G:$G,A7)) -> 0 | M7: =IF(A7="","",SUMIFS(Chicks!$P:$P,Chicks!$G:$G,A7)) -> 0 | N7: =IF($J7="","",RANK($J7,$J$2:$J$998,0)) -> 5 | O7: =SUM(G7/F7) -> 0.83333333
A8: ZA-2020-OP-17032 | B8: 17032 | C8: HEN | D8: =IFERROR(AVERAGEIF(Chicks!$G:$G, $A8, Chicks!$H:$H), "") -> 81 | E8: ACTIVE | F8: =IF(A8="","",COUNTIF(Chicks!$G:$G,A8)) -> 6 | G8: =IF(A8="","",COUNTIFS(Chicks!$G:$G,A8,Chicks!$I:$I,"Yes")) -> 3 | H8: =IF(A8="","",SUMIFS(Chicks!$J:$J,Chicks!$G:$G,A8)) -> 3 | I8: =IF(A8="","",COUNTIFS(Chicks!$G:$G,A8,Chicks!$I:$I,"No")) -> 3 | J8: =IF(A8="","",IFERROR(AVERAGEIF(Chicks!$G:$G,A8,Chicks!$M:$M),"")) -> 0.63230393 | K8: =IF(A8="","",SUMIFS(Chicks!$N:$N,Chicks!$G:$G,A8)) -> 0 | L8: =IF(A8="","",SUMIFS(Chicks!$O:$O,Chicks!$G:$G,A8)) -> 0 | M8: =IF(A8="","",SUMIFS(Chicks!$P:$P,Chicks!$G:$G,A8)) -> 1 | N8: =IF($J8="","",RANK($J8,$J$2:$J$998,0)) -> 3 | O8: =SUM(G8/F8) -> 0.5
A9: ZA-2022-DUVE-255 | B9: 255 | C9: HEN | D9: =IFERROR(AVERAGEIF(Chicks!$G:$G, $A9, Chicks!$H:$H), "") -> 80.714286 | E9: ACTIVE | F9: =IF(A9="","",COUNTIF(Chicks!$G:$G,A9)) -> 7 | G9: =IF(A9="","",COUNTIFS(Chicks!$G:$G,A9,Chicks!$I:$I,"Yes")) -> 1 | H9: =IF(A9="","",SUMIFS(Chicks!$J:$J,Chicks!$G:$G,A9)) -> 2 | I9: =IF(A9="","",COUNTIFS(Chicks!$G:$G,A9,Chicks!$I:$I,"No")) -> 6 | J9: =IF(A9="","",IFERROR(AVERAGEIF(Chicks!$G:$G,A9,Chicks!$M:$M),"")) -> 0.65702929 | K9: =IF(A9="","",SUMIFS(Chicks!$N:$N,Chicks!$G:$G,A9)) -> 1 | L9: =IF(A9="","",SUMIFS(Chicks!$O:$O,Chicks!$G:$G,A9)) -> 0 | M9: =IF(A9="","",SUMIFS(Chicks!$P:$P,Chicks!$G:$G,A9)) -> 1 | N9: =IF($J9="","",RANK($J9,$J$2:$J$998,0)) -> 1 | O9: =SUM(G9/F9) -> 0.14285714
A10: ZA-2022-DUVE-243 | B10: 243 | C10: HEN | D10: =IFERROR(AVERAGEIF(Chicks!$G:$G, $A10, Chicks!$H:$H), "") -> 78.75 | E10: ACTIVE | F10: =IF(A10="","",COUNTIF(Chicks!$G:$G,A10)) -> 5 | G10: =IF(A10="","",COUNTIFS(Chicks!$G:$G,A10,Chicks!$I:$I,"Yes")) -> 2 | H10: =IF(A10="","",SUMIFS(Chicks!$J:$J,Chicks!$G:$G,A10)) -> 1 | I10: =IF(A10="","",COUNTIFS(Chicks!$G:$G,A10,Chicks!$I:$I,"No")) -> 3 | J10: =IF(A10="","",IFERROR(AVERAGEIF(Chicks!$G:$G,A10,Chicks!$M:$M),"")) -> 0.63784461 | K10: =IF(A10="","",SUMIFS(Chicks!$N:$N,Chicks!$G:$G,A10)) -> 0 | L10: =IF(A10="","",SUMIFS(Chicks!$O:$O,Chicks!$G:$G,A10)) -> 0 | M10: =IF(A10="","",SUMIFS(Chicks!$P:$P,Chicks!$G:$G,A10)) -> 0 | N10: =IF($J10="","",RANK($J10,$J$2:$J$998,0)) -> 2 | O10: =SUM(G10/F10) -> 0.4
A11: ZA-2019-OP-9331 | B11: 9331 | C11: HEN | D11: =IFERROR(AVERAGEIF(Chicks!$G:$G, $A11, Chicks!$H:$H), "") -> 77.5 | E11: ACTIVE | F11: =IF(A11="","",COUNTIF(Chicks!$G:$G,A11)) -> 6 | G11: =IF(A11="","",COUNTIFS(Chicks!$G:$G,A11,Chicks!$I:$I,"Yes")) -> 4 | H11: =IF(A11="","",SUMIFS(Chicks!$J:$J,Chicks!$G:$G,A11)) -> 2 | I11: =IF(A11="","",COUNTIFS(Chicks!$G:$G,A11,Chicks!$I:$I,"No")) -> 2 | J11: =IF(A11="","",IFERROR(AVERAGEIF(Chicks!$G:$G,A11,Chicks!$M:$M),"")) -> 0.57949766 | K11: =IF(A11="","",SUMIFS(Chicks!$N:$N,Chicks!$G:$G,A11)) -> 0 | L11: =IF(A11="","",SUMIFS(Chicks!$O:$O,Chicks!$G:$G,A11)) -> 0 | M11: =IF(A11="","",SUMIFS(Chicks!$P:$P,Chicks!$G:$G,A11)) -> 0 | N11: =IF($J11="","",RANK($J11,$J$2:$J$998,0)) -> 4 | O11: =SUM(G11/F11) -> 0.66666667
F12: =IF(A12="","",COUNTIF(Chicks!$G:$G,A12)) | G12: =IF(A12="","",COUNTIFS(Chicks!$G:$G,A12,Chicks!$I:$I,"Yes")) | H12: =IF(A12="","",SUMIFS(Chicks!$J:$J,Chicks!$G:$G,A12)) | I12: =IF(A12="","",COUNTIFS(Chicks!$G:$G,A12,Chicks!$I:$I,"No")) | J12: =IF(A12="","",IFERROR(AVERAGEIF(Chicks!$G:$G,A12,Chicks!$M:$M),"")) | K12: =IF(A12="","",SUMIFS(Chicks!$N:$N,Chicks!$G:$G,A12)) | L12: =IF(A12="","",SUMIFS(Chicks!$O:$O,Chicks!$G:$G,A12)) | M12: =IF(A12="","",SUMIFS(Chicks!$P:$P,Chicks!$G:$G,A12)) | N12: =IF($J12="","",RANK($J12,$J$2:$J$998,0))
F13: =IF(A13="","",COUNTIF(Chicks!$G:$G,A13)) | G13: =IF(A13="","",COUNTIFS(Chicks!$G:$G,A13,Chicks!$I:$I,"Yes")) | H13: =IF(A13="","",SUMIFS(Chicks!$J:$J,Chicks!$G:$G,A13)) | I13: =IF(A13="","",COUNTIFS(Chicks!$G:$G,A13,Chicks!$I:$I,"No")) | J13: =IF(A13="","",IFERROR(AVERAGEIF(Chicks!$G:$G,A13,Chicks!$M:$M),"")) | K13: =IF(A13="","",SUMIFS(Chicks!$N:$N,Chicks!$G:$G,A13)) | L13: =IF(A13="","",SUMIFS(Chicks!$O:$O,Chicks!$G:$G,A13)) | M13: =IF(A13="","",SUMIFS(Chicks!$P:$P,Chicks!$G:$G,A13)) | N13: =IF($J13="","",RANK($J13,$J$2:$J$998,0))
F14: =IF(A14="","",COUNTIF(Chicks!$G:$G,A14)) | G14: =IF(A14="","",COUNTIFS(Chicks!$G:$G,A14,Chicks!$I:$I,"Yes")) | H14: =IF(A14="","",SUMIFS(Chicks!$J:$J,Chicks!$G:$G,A14)) | I14: =IF(A14="","",COUNTIFS(Chicks!$G:$G,A14,Chicks!$I:$I,"No")) | J14: =IF(A14="","",IFERROR(AVERAGEIF(Chicks!$G:$G,A14,Chicks!$M:$M),"")) | K14: =IF(A14="","",SUMIFS(Chicks!$N:$N,Chicks!$G:$G,A14)) | L14: =IF(A14="","",SUMIFS(Chicks!$O:$O,Chicks!$G:$G,A14)) | M14: =IF(A14="","",SUMIFS(Chicks!$P:$P,Chicks!$G:$G,A14)) | N14: =IF($J14="","",RANK($J14,$J$2:$J$998,0))
F15: =IF(A15="","",COUNTIF(Chicks!$G:$G,A15)) | G15: =IF(A15="","",COUNTIFS(Chicks!$G:$G,A15,Chicks!$I:$I,"Yes")) | H15: =IF(A15="","",SUMIFS(Chicks!$J:$J,Chicks!$G:$G,A15)) | I15: =IF(A15="","",COUNTIFS(Chicks!$G:$G,A15,Chicks!$I:$I,"No")) | J15: =IF(A15="","",IFERROR(AVERAGEIF(Chicks!$G:$G,A15,Chicks!$M:$M),"")) | K15: =IF(A15="","",SUMIFS(Chicks!$N:$N,Chicks!$G:$G,A15)) | L15: =IF(A15="","",SUMIFS(Chicks!$O:$O,Chicks!$G:$G,A15)) | M15: =IF(A15="","",SUMIFS(Chicks!$P:$P,Chicks!$G:$G,A15)) | N15: =IF($J15="","",RANK($J15,$J$2:$J$998,0))
F16: =IF(A16="","",COUNTIF(Chicks!$G:$G,A16)) | G16: =IF(A16="","",COUNTIFS(Chicks!$G:$G,A16,Chicks!$I:$I,"Yes")) | H16: =IF(A16="","",SUMIFS(Chicks!$J:$J,Chicks!$G:$G,A16)) | I16: =IF(A16="","",COUNTIFS(Chicks!$G:$G,A16,Chicks!$I:$I,"No")) | J16: =IF(A16="","",IFERROR(AVERAGEIF(Chicks!$G:$G,A16,Chicks!$M:$M),"")) | K16: =IF(A16="","",SUMIFS(Chicks!$N:$N,Chicks!$G:$G,A16)) | L16: =IF(A16="","",SUMIFS(Chicks!$O:$O,Chicks!$G:$G,A16)) | M16: =IF(A16="","",SUMIFS(Chicks!$P:$P,Chicks!$G:$G,A16)) | N16: =IF($J16="","",RANK($J16,$J$2:$J$998,0))
F17: =IF(A17="","",COUNTIF(Chicks!$G:$G,A17)) | G17: =IF(A17="","",COUNTIFS(Chicks!$G:$G,A17,Chicks!$I:$I,"Yes")) | H17: =IF(A17="","",SUMIFS(Chicks!$J:$J,Chicks!$G:$G,A17)) | I17: =IF(A17="","",COUNTIFS(Chicks!$G:$G,A17,Chicks!$I:$I,"No")) | J17: =IF(A17="","",IFERROR(AVERAGEIF(Chicks!$G:$G,A17,Chicks!$M:$M),"")) | K17: =IF(A17="","",SUMIFS(Chicks!$N:$N,Chicks!$G:$G,A17)) | L17: =IF(A17="","",SUMIFS(Chicks!$O:$O,Chicks!$G:$G,A17)) | M17: =IF(A17="","",SUMIFS(Chicks!$P:$P,Chicks!$G:$G,A17)) | N17: =IF($J17="","",RANK($J17,$J$2:$J$998,0))
